Workbook

Sheet SkillData
A1: skill_idx | B1: #2번째 스킬 참조 | C1: #3번째 스킬 참조 | D1: name_id | E1: #name_id | F1: desc_id | G1: #desc_id | H1: #디테일 | I1: skill_type | J1: Key1 | K1: Con1 | L1: Per1 | M1: Val1 | N1: Key2 | O1: Con2 | P1: Per2 | Q1: Val2 | R1: Key3 | S1: Con3 | T1: Per3 | U1: Val3
A2: 10001 | B2: =A2+10000 -> 20001 | C2: =B2+10000 -> 30001 | D2: ="SkillName."&A2 -> SkillName.10001 | E2: 집중력1 | F2: ="SkillDesc."&A2 -> SkillDesc.10001 | G2: 3구부터 누적되는 투구 수 마다 선구 +{0} | H2: 매구 누적이므로 25value | I2: Hitting | J2: =IFERROR(VLOOKUP(A2,'#level_value'!$A$2:$H$9999,3,FALSE),"") -> Vision | K2: =IFERROR(VLOOKUP(A2,'#level_value'!$A$2:$H$9999,4,FALSE),"") -> Cumulative | L2: =IFERROR(VLOOKUP(A2,'#level_value'!$A$2:$H$9999,7,FALSE),"") -> [0,0,0,0,0] | M2: =IFERROR(VLOOKUP(A2,'#level_value'!$A$2:$H$9999,8,FALSE),"") -> [5,8,14,20,30] | N2: =IFERROR(VLOOKUP(B2,'#level_value'!$A$2:$H$9999,3,FALSE),"") | O2: =IFERROR(VLOOKUP(B2,'#level_value'!$A$2:$H$9999,4,FALSE),"") | P2: =IFERROR(VLOOKUP(B2,'#level_value'!$A$2:$H$9999,7,FALSE),"") | Q2: =IFERROR(VLOOKUP(B2,'#level_value'!$A$2:$H$9999,8,FALSE),"") | R2: =IFERROR(VLOOKUP(C2,'#level_value'!$A$2:$H$9999,3,FALSE),"") | S2: =IFERROR(VLOOKUP(C2,'#level_value'!$A$2:$H$9999,4,FALSE),"") | T2: =IFERROR(VLOOKUP(C2,'#level_value'!$A$2:$H$9999,7,FALSE),"") | U2: =IFERROR(VLOOKUP(C2,'#level_value'!$A$2:$H$9999,8,FALSE),"")
A3: =A2+1 -> 10002 | B3: =A3+10000 -> 20002 | C3: =B3+10000 -> 30002 | D3: ="SkillName."&A3 -> SkillName.10002 | E3: 집중력2 | F3: ="SkillDesc."&A3 -> SkillDesc.10002 | G3: 2구부터 누적되는 투구 수 마다 선구 +{0} | I3: Hitting | J3: =IFERROR(VLOOKUP(A3,'#level_value'!$A$2:$H$9999,3,FALSE),"") -> Vision | K3: =IFERROR(VLOOKUP(A3,'#level_value'!$A$2:$H$9999,4,FALSE),"") -> Cumulative | L3: =IFERROR(VLOOKUP(A3,'#level_value'!$A$2:$H$9999,7,FALSE),"") -> [0,0,0,0,0] | M3: =IFERROR(VLOOKUP(A3,'#level_value'!$A$2:$H$9999,8,FALSE),"") -> [10,16,22,34,50] | N3: =IFERROR(VLOOKUP(B3,'#level_value'!$A$2:$H$9999,3,FALSE),"") | O3: =IFERROR(VLOOKUP(B3,'#level_value'!$A$2:$H$9999,4,FALSE),"") | P3: =IFERROR(VLOOKUP(B3,'#level_value'!$A$2:$H$9999,7,FALSE),"") | Q3: =IFERROR(VLOOKUP(B3,'#level_value'!$A$2:$H$9999,8,FALSE),"") | R3: =IFERROR(VLOOKUP(C3,'#level_value'!$A$2:$H$9999,3,FALSE),"") | S3: =IFERROR(VLOOKUP(C3,'#level_value'!$A$2:$H$9999,4,FALSE),"") | T3: =IFERROR(VLOOKUP(C3,'#level_value'!$A$2:$H$9999,7,FALSE),"") | U3: =IFERROR(VLOOKUP(C3,'#level_value'!$A$2:$H$9999,8,FALSE),"")
A4: =A3+1 -> 10003 | B4: =A4+10000 -> 20003 | C4: =B4+10000 -> 30003 | D4: ="SkillName."&A4 -> SkillName.10003 | E4: 집중력3 | F4: ="SkillDesc."&A4 -> SkillDesc.10003 | G4: 2구부터 누적되는 투구 수 마다 선구 +{0}, 타구속도 +{1} | I4: Hitting | J4: =IFERROR(VLOOKUP(A4,'#level_value'!$A$2:$H$9999,3,FALSE),"") -> Vision | K4: =IFERROR(VLOOKUP(A4,'#level_value'!$A$2:$H$9999,4,FALSE),"") -> Cumulative | L4: =IFERROR(VLOOKUP(A4,'#level_value'!$A$2:$H$9999,7,FALSE),"") -> [0,0,0,0,0] | M4: =IFERROR(VLOOKUP(A4,'#level_value'!$A$2:$H$9999,8,FALSE),"") -> [10,16,22,34,50] | N4: =IFERROR(VLOOKUP(B4,'#level_value'!$A$2:$H$9999,3,FALSE),"") -> HittingSpeed | O4: =IFERROR(VLOOKUP(B4,'#level_value'!$A$2:$H$9999,4,FALSE),"") -> AfterHit | P4: =IFERROR(VLOOKUP(B4,'#level_value'!$A$2:$H$9999,7,FALSE),"") -> [0,0,0,0,0] | Q4: =IFERROR(VLOOKUP(B4,'#level_value'!$A$2:$H$9999,8,FALSE),"") -> [30000,50000,70000,100000,150000] | R4: =IFERROR(VLOOKUP(C4,'#level_value'!$A$2:$H$9999,3,FALSE),"") | S4: =IFERROR(VLOOKUP(C4,'#level_value'!$A$2:$H$9999,4,FALSE),"") | T4: =IFERROR(VLOOKUP(C4,'#level_value'!$A$2:$H$9999,7,FALSE),"") | U4: =IFERROR(VLOOKUP(C4,'#level_value'!$A$2:$H$9999,8,FALSE),"")
A5: =A4+1 -> 10004 | B5: =A5+10000 -> 20004 | C5: =B5+10000 -> 30004 | D5: ="SkillName."&A5 -> SkillName.10004 | E5: 우완킬러1 | F5: ="SkillDesc."&A5 -> SkillDesc.10004 | G5: 우투수 시 {0}%확률로 컨택 +{0} | H5: 우투수는 65%이므로 40 value | I5: Hitting | J5: =IFERROR(VLOOKUP(A5,'#level_value'!$A$2:$H$9999,3,FALSE),"") -> Contact | K5: =IFERROR(VLOOKUP(A5,'#level_value'!$A$2:$H$9999,4,FALSE),"") -> RightPitcher | L5: =IFERROR(VLOOKUP(A5,'#level_value'!$A$2:$H$9999,7,FALSE),"") -> [30,35,40,45,50] | M5: =IFERROR(VLOOKUP(A5,'#level_value'!$A$2:$H$9999,8,FALSE),"") -> [5,8,14,20,30] | N5: =IFERROR(VLOOKUP(B5,'#level_value'!$A$2:$H$9999,3,FALSE),"") | O5: =IFERROR(VLOOKUP(B5,'#level_value'!$A$2:$H$9999,4,FALSE),"") | P5: =IFERROR(VLOOKUP(B5,'#level_value'!$A$2:$H$9999,7,FALSE),"") | Q5: =IFERROR(VLOOKUP(B5,'#level_value'!$A$2:$H$9999,8,FALSE),"") | R5: =IFERROR(VLOOKUP(C5,'#level_value'!$A$2:$H$9999,3,FALSE),"") | S5: =IFERROR(VLOOKUP(C5,'#level_value'!$A$2:$H$9999,4,FALSE),"") | T5: =IFERROR(VLOOKUP(C5,'#level_value'!$A$2:$H$9999,7,FALSE),"") | U5: =IFERROR(VLOOKUP(C5,'#level_value'!$A$2:$H$9999,8,FALSE),"")
A6: =A5+1 -> 10005 | B6: =A6+10000 -> 20005 | C6: =B6+10000 -> 30005 | D6: ="SkillName."&A6 -> SkillName.10005 | E6: 우완킬러2 | F6: ="SkillDesc."&A6 -> SkillDesc.10005 | G6: 우투수 시 {0}%확률로 컨택 +{0} | I6: Hitting | J6: =IFERROR(VLOOKUP(A6,'#level_value'!$A$2:$H$9999,3,FALSE),"") -> Contact | K6: =IFERROR(VLOOKUP(A6,'#level_value'!$A$2:$H$9999,4,FALSE),"") -> RightPitcher | L6: =IFERROR(VLOOKUP(A6,'#level_value'!$A$2:$H$9999,7,FALSE),"") -> [50,55,60,65,70] | M6: =IFERROR(VLOOKUP(A6,'#level_value'!$A$2:$H$9999,8,FALSE),"") -> [10,16,22,34,50] | N6: =IFERROR(VLOOKUP(B6,'#level_value'!$A$2:$H$9999,3,FALSE),"") | O6: =IFERROR(VLOOKUP(B6,'#level_value'!$A$2:$H$9999,4,FALSE),"") | P6: =IFERROR(VLOOKUP(B6,'#level_value'!$A$2:$H$9999,7,FALSE),"") | Q6: =IFERROR(VLOOKUP(B6,'#level_value'!$A$2:$H$9999,8,FALSE),"") | R6: =IFERROR(VLOOKUP(C6,'#level_value'!$A$2:$H$9999,3,FALSE),"") | S6: =IFERROR(VLOOKUP(C6,'#level_value'!$A$2:$H$9999,4,FALSE),"") | T6: =IFERROR(VLOOKUP(C6,'#level_value'!$A$2:$H$9999,7,FALSE),"") | U6: =IFERROR(VLOOKUP(C6,'#level_value'!$A$2:$H$9999,8,FALSE),"")
A7: =A6+1 -> 10006 | B7: =A7+10000 -> 20006 | C7: =B7+10000 -> 30006 | D7: ="SkillName."&A7 -> SkillName.10006 | E7: 우완킬러3 | F7: ="SkillDesc."&A7 -> SkillDesc.10006 | G7: 우투수 시 100%확률로 컨택 +{0}, 선구+{0} | I7: Hitting | J7: =IFERROR(VLOOKUP(A7,'#level_value'!$A$2:$H$9999,3,FALSE),"") -> Contact | K7: =IFERROR(VLOOKUP(A7,'#level_value'!$A$2:$H$9999,4,FALSE),"") -> RightPitcher | L7: =IFERROR(VLOOKUP(A7,'#level_value'!$A$2:$H$9999,7,FALSE),"") -> [0,0,0,0,0] | M7: =IFERROR(VLOOKUP(A7,'#level_value'!$A$2:$H$9999,8,FALSE),"") -> [10,16,22,34,50] | N7: =IFERROR(VLOOKUP(B7,'#level_value'!$A$2:$H$9999,3,FALSE),"") -> Vision | O7: =IFERROR(VLOOKUP(B7,'#level_value'!$A$2:$H$9999,4,FALSE),"") -> MainActivated | P7: =IFERROR(VLOOKUP(B7,'#level_value'!$A$2:$H$9999,7,FALSE),"") -> [0,0,0,0,0] | Q7: =IFERROR(VLOOKUP(B7,'#level_value'!$A$2:$H$9999,8,FALSE),"") -> [5,8,11,18,25] | R7: =IFERROR(VLOOKUP(C7,'#level_value'!$A$2:$H$9999,3,FALSE),"") | S7: =IFERROR(VLOOKUP(C7,'#level_value'!$A$2:$H$9999,4,FALSE),"") | T7: =IFERROR(VLOOKUP(C7,'#level_value'!$A$2:$H$9999,7,FALSE),"") | U7: =IFERROR(VLOOKUP(C7,'#level_value'!$A$2:$H$9999,8,FALSE),"")
A8: =A7+1 -> 10007 | B8: =A8+10000 -> 20007 | C8: =B8+10000 -> 30007 | D8: ="SkillName."&A8 -> SkillName.10007 | E8: 좌완킬러1 | F8: ="SkillDesc."&A8 -> SkillDesc.10007 | G8: 좌투수 시 {0}%확률로 파워 +{0} | H8: 좌투수는 35%이므로 60 value | I8: Hitting | J8: =IFERROR(VLOOKUP(A8,'#level_value'!$A$2:$H$9999,3,FALSE),"") -> Power | K8: =IFERROR(VLOOKUP(A8,'#level_value'!$A$2:$H$9999,4,FALSE),"") -> LeftPitcher | L8: =IFERROR(VLOOKUP(A8,'#level_value'!$A$2:$H$9999,7,FALSE),"") -> [30,35,40,45,50] | M8: =IFERROR(VLOOKUP(A8,'#level_value'!$A$2:$H$9999,8,FALSE),"") -> [5,8,14,20,30] | N8: =IFERROR(VLOOKUP(B8,'#level_value'!$A$2:$H$9999,3,FALSE),"") | O8: =IFERROR(VLOOKUP(B8,'#level_value'!$A$2:$H$9999,4,FALSE),"") | P8: =IFERROR(VLOOKUP(B8,'#level_value'!$A$2:$H$9999,7,FALSE),"") | Q8: =IFERROR(VLOOKUP(B8,'#level_value'!$A$2:$H$9999,8,FALSE),"") | R8: =IFERROR(VLOOKUP(C8,'#level_value'!$A$2:$H$9999,3,FALSE),"") | S8: =IFERROR(VLOOKUP(C8,'#level_value'!$A$2:$H$9999,4,FALSE),"") | T8: =IFERROR(VLOOKUP(C8,'#level_value'!$A$2:$H$9999,7,FALSE),"") | U8: =IFERROR(VLOOKUP(C8,'#level_value'!$A$2:$H$9999,8,FALSE),"")
A9: =A8+1 -> 10008 | B9: =A9+10000 -> 20008 | C9: =B9+10000 -> 30008 | D9: ="SkillName."&A9 -> SkillName.10008 | E9: 좌완킬러2 | F9: ="SkillDesc."&A9 -> SkillDesc.10008 | G9: 좌투수 시 {0}%확률로 파워 +{0} | I9: Hitting | J9: =IFERROR(VLOOKUP(A9,'#level_value'!$A$2:$H$9999,3,FALSE),"") -> Power | K9: =IFERROR(VLOOKUP(A9,'#level_value'!$A$2:$H$9999,4,FALSE),"") -> LeftPitcher | L9: =IFERROR(VLOOKUP(A9,'#level_value'!$A$2:$H$9999,7,FALSE),"") -> [50,55,60,65,70] | M9: =IFERROR(VLOOKUP(A9,'#level_value'!$A$2:$H$9999,8,FALSE),"") -> [10,16,22,34,50] | N9: =IFERROR(VLOOKUP(B9,'#level_value'!$A$2:$H$9999,3,FALSE),"") | O9: =IFERROR(VLOOKUP(B9,'#level_value'!$A$2:$H$9999,4,FALSE),"") | P9: =IFERROR(VLOOKUP(B9,'#level_value'!$A$2:$H$9999,7,FALSE),"") | Q9: =IFERROR(VLOOKUP(B9,'#level_value'!$A$2:$H$9999,8,FALSE),"") | R9: =IFERROR(VLOOKUP(C9,'#level_value'!$A$2:$H$9999,3,FALSE),"") | S9: =IFERROR(VLOOKUP(C9,'#level_value'!$A$2:$H$9999,4,FALSE),"") | T9: =IFERROR(VLOOKUP(C9,'#level_value'!$A$2:$H$9999,7,FALSE),"") | U9: =IFERROR(VLOOKUP(C9,'#level_value'!$A$2:$H$9999,8,FALSE),"")
A10: =A9+1 -> 10009 | B10: =A10+10000 -> 20009 | C10: =B10+10000 -> 30009 | D10: ="SkillName."&A10 -> SkillName.10009 | E10: 좌완킬러3 | F10: ="SkillDesc."&A10 -> SkillDesc.10009 | G10: 좌투수 시 100%확률로 파워 +{0}, 선구+{0} | I10: Hitting | J10: =IFERROR(VLOOKUP(A10,'#level_value'!$A$2:$H$9999,3,FALSE),"") -> Power | K10: =IFERROR(VLOOKUP(A10,'#level_value'!$A$2:$H$9999,4,FALSE),"") -> LeftPitcher | L10: =IFERROR(VLOOKUP(A10,'#level_value'!$A$2:$H$9999,7,FALSE),"") -> [0,0,0,0,0] | M10: =IFERROR(VLOOKUP(A10,'#level_value'!$A$2:$H$9999,8,FALSE),"") -> [10,16,22,34,50] | N10: =IFERROR(VLOOKUP(B10,'#level_value'!$A$2:$H$9999,3,FALSE),"") -> Vision | O10: =IFERROR(VLOOKUP(B10,'#level_value'!$A$2:$H$9999,4,FALSE),"") -> MainActivated | P10: =IFERROR(VLOOKUP(B10,'#level_value'!$A$2:$H$9999,7,FALSE),"") -> [0,0,0,0,0] | Q10: =IFERROR(VLOOKUP(B10,'#level_value'!$A$2:$H$9999,8,FALSE),"") -> [5,8,11,18,25] | R10: =IFERROR(VLOOKUP(C10,'#level_value'!$A$2:$H$9999,3,FALSE),"") | S10: =IFERROR(VLOOKUP(C10,'#level_value'!$A$2:$H$9999,4,FALSE),"") | T10: =IFERROR(VLOOKUP(C10,'#level_value'!$A$2:$H$9999,7,FALSE),"") | U10: =IFERROR(VLOOKUP(C10,'#level_value'!$A$2:$H$9999,8,FALSE),"")
A11: =A10+1 -> 10010 | B11: =A11+10000 -> 20010 | C11: =B11+10000 -> 30010 | D11: ="SkillName."&A11 -> SkillName.10010 | E11: 끝내기안타 | F11: ="SkillDesc."&A11 -> SkillDesc.10010 | G11: 9회 타격 시 컨택 +{0} | H11: 9회는 25% 이므로 80 value | I11: Hitting | J11: =IFERROR(VLOOKUP(A11,'#level_value'!$A$2:$H$9999,3,FALSE),"") -> Contact | K11: =IFERROR(VLOOKUP(A11,'#level_value'!$A$2:$H$9999,4,FALSE),"") -> Walkoff | L11: =IFERROR(VLOOKUP(A11,'#level_value'!$A$2:$H$9999,7,FALSE),"") -> [0,0,0,0,0] | M11: =IFERROR(VLOOKUP(A11,'#level_value'!$A$2:$H$9999,8,FALSE),"") -> [5,8,14,20,30] | N11: =IFERROR(VLOOKUP(B11,'#level_value'!$A$2:$H$9999,3,FALSE),"") | O11: =IFERROR(VLOOKUP(B11,'#level_value'!$A$2:$H$9999,4,FALSE),"") | P11: =IFERROR(VLOOKUP(B11,'#level_value'!$A$2:$H$9999,7,FALSE),"") | Q11: =IFERROR(VLOOKUP(B11,'#level_value'!$A$2:$H$9999,8,FALSE),"") | R11: =IFERROR(VLOOKUP(C11,'#level_value'!$A$2:$H$9999,3,FALSE),"") | S11: =IFERROR(VLOOKUP(C11,'#level_value'!$A$2:$H$9999,4,FALSE),"") | T11: =IFERROR(VLOOKUP(C11,'#level_value'!$A$2:$H$9999,7,FALSE),"") | U11: =IFERROR(VLOOKUP(C11,'#level_value'!$A$2:$H$9999,8,FALSE),"")
A12: =A11+1 -> 10011 | B12: =A12+10000 -> 20011 | C12: =B12+10000 -> 30011 | D12: ="SkillName."&A12 -> SkillName.10011 | E12: 끝내기홈런 | F12: ="SkillDesc."&A12 -> SkillDesc.10011 | G12: 9회 타격 시 파워 +{0} | I12: Hitting | J12: =IFERROR(VLOOKUP(A12,'#level_value'!$A$2:$H$9999,3,FALSE),"") -> Power | K12: =IFERROR(VLOOKUP(A12,'#level_value'!$A$2:$H$9999,4,FALSE),"") -> Walkoff | L12: =IFERROR(VLOOKUP(A12,'#level_value'!$A$2:$H$9999,7,FALSE),"") -> [0,0,0,0,0] | M12: =IFERROR(VLOOKUP(A12,'#level_value'!$A$2:$H$9999,8,FALSE),"") -> [10,16,22,34,50] | N12: =IFERROR(VLOOKUP(B12,'#level_value'!$A$2:$H$9999,3,FALSE),"") | O12: =IFERROR(VLOOKUP(B12,'#level_value'!$A$2:$H$9999,4,FALSE),"") | P12: =IFERROR(VLOOKUP(B12,'#level_value'!$A$2:$H$9999,7,FALSE),"") | Q12: =IFERROR(VLOOKUP(B12,'#level_value'!$A$2:$H$9999,8,FALSE),"") | R12: =IFERROR(VLOOKUP(C12,'#level_value'!$A$2:$H$9999,3,FALSE),"") | S12: =IFERROR(VLOOKUP(C12,'#level_value'!$A$2:$H$9999,4,FALSE),"") | T12: =IFERROR(VLOOKUP(C12,'#level_value'!$A$2:$H$9999,7,FALSE),"") | U12: =IFERROR(VLOOKUP(C12,'#level_value'!$A$2:$H$9999,8,FALSE),"")
A13: =A12+1 -> 10012 | B13: =A13+10000 -> 20012 | C13: =B13+10000 -> 30012 | D13: ="SkillName."&A13 -> SkillName.10012 | E13: 초구1 | F13: ="SkillDesc."&A13 -> SkillDesc.10012 | G13: 초구에 {0}%확률로 파워 +{0} | H13: 초구는 100%이므로 30 value | I13: Hitting | J13: =IFERROR(VLOOKUP(A13,'#level_value'!$A$2:$H$9999,3,FALSE),"") -> Power | K13: =IFERROR(VLOOKUP(A13,'#level_value'!$A$2:$H$9999,4,FALSE),"") -> FirstPitch | L13: =IFERROR(VLOOKUP(A13,'#level_value'!$A$2:$H$9999,7,FALSE),"") -> [30,35,40,45,50] | M13: =IFERROR(VLOOKUP(A13,'#level_value'!$A$2:$H$9999,8,FALSE),"") -> [5,8,14,20,30] | N13: =IFERROR(VLOOKUP(B13,'#level_value'!$A$2:$H$9999,3,FALSE),"") | O13: =IFERROR(VLOOKUP(B13,'#level_value'!$A$2:$H$9999,4,FALSE),"") | P13: =IFERROR(VLOOKUP(B13,'#level_value'!$A$2:$H$9999,7,FALSE),"") | Q13: =IFERROR(VLOOKUP(B13,'#level_value'!$A$2:$H$9999,8,FALSE),"") | R13: =IFERROR(VLOOKUP(C13,'#level_value'!$A$2:$H$9999,3,FALSE),"") | S13: =IFERROR(VLOOKUP(C13,'#level_value'!$A$2:$H$9999,4,FALSE),"") | T13: =IFERROR(VLOOKUP(C13,'#level_value'!$A$2:$H$9999,7,FALSE),"") | U13: =IFERROR(VLOOKUP(C13,'#level_value'!$A$2:$H$9999,8,FALSE),"")
A14: =A13+1 -> 10013 | B14: =A14+10000 -> 20013 | C14: =B14+10000 -> 30013 | D14: ="SkillName."&A14 -> SkillName.10013 | E14: 초구2 | F14: ="SkillDesc."&A14 -> SkillDesc.10013 | G14: 초구에 {0}%확률로 파워 +{0} | I14: Hitting | J14: =IFERROR(VLOOKUP(A14,'#level_value'!$A$2:$H$9999,3,FALSE),"") -> Power | K14: =IFERROR(VLOOKUP(A14,'#level_value'!$A$2:$H$9999,4,FALSE),"") -> FirstPitch | L14: =IFERROR(VLOOKUP(A14,'#level_value'!$A$2:$H$9999,7,FALSE),"") -> [50,55,60,65,70] | M14: =IFERROR(VLOOKUP(A14,'#level_value'!$A$2:$H$9999,8,FALSE),"") -> [10,16,22,34,50] | N14: =IFERROR(VLOOKUP(B14,'#level_value'!$A$2:$H$9999,3,FALSE),"") | O14: =IFERROR(VLOOKUP(B14,'#level_value'!$A$2:$H$9999,4,FALSE),"") | P14: =IFERROR(VLOOKUP(B14,'#level_value'!$A$2:$H$9999,7,FALSE),"") | Q14: =IFERROR(VLOOKUP(B14,'#level_value'!$A$2:$H$9999,8,FALSE),"") | R14: =IFERROR(VLOOKUP(C14,'#level_value'!$A$2:$H$9999,3,FALSE),"") | S14: =IFERROR(VLOOKUP(C14,'#level_value'!$A$2:$H$9999,4,FALSE),"") | T14: =IFERROR(VLOOKUP(C14,'#level_value'!$A$2:$H$9999,7,FALSE),"") | U14: =IFERROR(VLOOKUP(C14,'#level_value'!$A$2:$H$9999,8,FALSE),"")
A15: =A14+1 -> 10014 | B15: =A15+10000 -> 20014 | C15: =B15+10000 -> 30014 | D15: ="SkillName."&A15 -> SkillName.10014 | E15: 초구3 | F15: ="SkillDesc."&A15 -> SkillDesc.10014 | G15: 초구에 100%확률로 파워 +{0}, 컨택+{0} | I15: Hitting | J15: =IFERROR(VLOOKUP(A15,'#level_value'!$A$2:$H$9999,3,FALSE),"") -> Power | K15: =IFERROR(VLOOKUP(A15,'#level_value'!$A$2:$H$9999,4,FALSE),"") -> FirstPitch | L15: =IFERROR(VLOOKUP(A15,'#level_value'!$A$2:$H$9999,7,FALSE),"") -> [0,0,0,0,0] | M15: =IFERROR(VLOOKUP(A15,'#level_value'!$A$2:$H$9999,8,FALSE),"") -> [10,16,22,34,50] | N15: =IFERROR(VLOOKUP(B15,'#level_value'!$A$2:$H$9999,3,FALSE),"") -> Contact | O15: =IFERROR(VLOOKUP(B15,'#level_value'!$A$2:$H$9999,4,FALSE),"") -> MainActivated | P15: =IFERROR(VLOOKUP(B15,'#level_value'!$A$2:$H$9999,7,FALSE),"") -> [0,0,0,0,0] | Q15: =IFERROR(VLOOKUP(B15,'#level_value'!$A$2:$H$9999,8,FALSE),"") -> [5,8,11,18,25] | R15: =IFERROR(VLOOKUP(C15,'#level_value'!$A$2:$H$9999,3,FALSE),"") | S15: =IFERROR(VLOOKUP(C15,'#level_value'!$A$2:$H$9999,4,FALSE),"") | T15: =IFERROR(VLOOKUP(C15,'#level_value'!$A$2:$H$9999,7,FALSE),"") | U15: =IFERROR(VLOOKUP(C15,'#level_value'!$A$2:$H$9999,8,FALSE),"")
A16: =A15+1 -> 10015 | B16: =A16+10000 -> 20015 | C16: =B16+10000 -> 30015 | D16: ="SkillName."&A16 -> SkillName.10015 | E16: 변화구1 | F16: ="SkillDesc."&A16 -> SkillDesc.10015 | G16: 변화구 타격시 타구속도 +{0}% | H16: 변화구는 40 value | I16: Hitting | J16: =IFERROR(VLOOKUP(A16,'#level_value'!$A$2:$H$9999,3,FALSE),"") -> HittingSpeed | K16: =IFERROR(VLOOKUP(A16,'#level_value'!$A$2:$H$9999,4,FALSE),"") -> BreakballHit | L16: =IFERROR(VLOOKUP(A16,'#level_value'!$A$2:$H$9999,7,FALSE),"") -> [0,0,0,0,0] | M16: =IFERROR(VLOOKUP(A16,'#level_value'!$A$2:$H$9999,8,FALSE),"") -> [30000,50000,70000,100000,150000] | N16: =IFERROR(VLOOKUP(B16,'#level_value'!$A$2:$H$9999,3,FALSE),"") | O16: =IFERROR(VLOOKUP(B16,'#level_value'!$A$2:$H$9999,4,FALSE),"") | P16: =IFERROR(VLOOKUP(B16,'#level_value'!$A$2:$H$9999,7,FALSE),"") | Q16: =IFERROR(VLOOKUP(B16,'#level_value'!$A$2:$H$9999,8,FALSE),"") | R16: =IFERROR(VLOOKUP(C16,'#level_value'!$A$2:$H$9999,3,FALSE),"") | S16: =IFERROR(VLOOKUP(C16,'#level_value'!$A$2:$H$9999,4,FALSE),"") | T16: =IFERROR(VLOOKUP(C16,'#level_value'!$A$2:$H$9999,7,FALSE),"") | U16: =IFERROR(VLOOKUP(C16,'#level_value'!$A$2:$H$9999,8,FALSE),"")
A17: =A16+1 -> 10016 | B17: =A17+10000 -> 20016 | C17: =B17+10000 -> 30016 | D17: ="SkillName."&A17 -> SkillName.10016 | E17: 변화구2 | F17: ="SkillDesc."&A17 -> SkillDesc.10016 | G17: 변화구 타격시 타구속도 +{0}%, 체크스윙 +{1}% | I17: Hitting | J17: =IFERROR(VLOOKUP(A17,'#level_value'!$A$2:$H$9999,3,FALSE),"") -> HittingSpeed | K17: =IFERROR(VLOOKUP(A17,'#level_value'!$A$2:$H$9999,4,FALSE),"") -> BreakballHit | L17: =IFERROR(VLOOKUP(A17,'#level_value'!$A$2:$H$9999,7,FALSE),"") -> [0,0,0,0,0] | M17: =IFERROR(VLOOKUP(A17,'#level_value'!$A$2:$H$9999,8,FALSE),"") -> [30000,50000,70000,100000,150000] | N17: =IFERROR(VLOOKUP(B17,'#level_value'!$A$2:$H$9999,3,FALSE),"") -> CheckSwing | O17: =IFERROR(VLOOKUP(B17,'#level_value'!$A$2:$H$9999,4,FALSE),"") -> NoCondition | P17: =IFERROR(VLOOKUP(B17,'#level_value'!$A$2:$H$9999,7,FALSE),"") -> [0,0,0,0,0] | Q17: =IFERROR(VLOOKUP(B17,'#level_value'!$A$2:$H$9999,8,FALSE),"") -> [30000,50000,70000,100000,150000] | R17: =IFERROR(VLOOKUP(C17,'#level_value'!$A$2:$H$9999,3,FALSE),"") | S17: =IFERROR(VLOOKUP(C17,'#level_value'!$A$2:$H$9999,4,FALSE),"") | T17: =IFERROR(VLOOKUP(C17,'#level_value'!$A$2:$H$9999,7,FALSE),"") | U17: =IFERROR(VLOOKUP(C17,'#level_value'!$A$2:$H$9999,8,FALSE),"")
A18: =A17+1 -> 10017 | B18: =A18+10000 -> 20017 | C18: =B18+10000 -> 30017 | D18: ="SkillName."&A18 -> SkillName.10017 | E18: 직구1 | F18: ="SkillDesc."&A18 -> SkillDesc.10017 | G18: 직구 타격시 타구속도 +{0}% | H18: 직구는 40 value | I18: Hitting | J18: =IFERROR(VLOOKUP(A18,'#level_value'!$A$2:$H$9999,3,FALSE),"") -> HittingSpeed | K18: =IFERROR(VLOOKUP(A18,'#level_value'!$A$2:$H$9999,4,FALSE),"") -> FastballHit | L18: =IFERROR(VLOOKUP(A18,'#level_value'!$A$2:$H$9999,7,FALSE),"") -> [0,0,0,0,0] | M18: =IFERROR(VLOOKUP(A18,'#level_value'!$A$2:$H$9999,8,FALSE),"") -> [30000,50000,70000,100000,150000] | N18: =IFERROR(VLOOKUP(B18,'#level_value'!$A$2:$H$9999,3,FALSE),"") | O18: =IFERROR(VLOOKUP(B18,'#level_value'!$A$2:$H$9999,4,FALSE),"") | P18: =IFERROR(VLOOKUP(B18,'#level_value'!$A$2:$H$9999,7,FALSE),"") | Q18: =IFERROR(VLOOKUP(B18,'#level_value'!$A$2:$H$9999,8,FALSE),"") | R18: =IFERROR(VLOOKUP(C18,'#level_value'!$A$2:$H$9999,3,FALSE),"") | S18: =IFERROR(VLOOKUP(C18,'#level_value'!$A$2:$H$9999,4,FALSE),"") | T18: =IFERROR(VLOOKUP(C18,'#level_value'!$A$2:$H$9999,7,FALSE),"") | U18: =IFERROR(VLOOKUP(C18,'#level_value'!$A$2:$H$9999,8,FALSE),"")
A19: =A18+1 -> 10018 | B19: =A19+10000 -> 20018 | C19: =B19+10000 -> 30018 | D19: ="SkillName."&A19 -> SkillName.10018 | E19: 직구2 | F19: ="SkillDesc."&A19 -> SkillDesc.10018 | G19: 직구 타격시 타구속도 +{0}%, 체크스윙 +{1}% | I19: Hitting | J19: =IFERROR(VLOOKUP(A19,'#level_value'!$A$2:$H$9999,3,FALSE),"") -> HittingSpeed | K19: =IFERROR(VLOOKUP(A19,'#level_value'!$A$2:$H$9999,4,FALSE),"") -> FastballHit | L19: =IFERROR(VLOOKUP(A19,'#level_value'!$A$2:$H$9999,7,FALSE),"") -> [0,0,0,0,0] | M19: =IFERROR(VLOOKUP(A19,'#level_value'!$A$2:$H$9999,8,FALSE),"") -> [30000,50000,70000,100000,150000] | N19: =IFERROR(VLOOKUP(B19,'#level_value'!$A$2:$H$9999,3,FALSE),"") -> CheckSwing | O19: =IFERROR(VLOOKUP(B19,'#level_value'!$A$2:$H$9999,4,FALSE),"") -> NoCondition | P19: =IFERROR(VLOOKUP(B19,'#level_value'!$A$2:$H$9999,7,FALSE),"") -> [0,0,0,0,0] | Q19: =IFERROR(VLOOKUP(B19,'#level_value'!$A$2:$H$9999,8,FALSE),"") -> [30000,50000,70000,100000,150000] | R19: =IFERROR(VLOOKUP(C19,'#level_value'!$A$2:$H$9999,3,FALSE),"") | S19: =IFERROR(VLOOKUP(C19,'#level_value'!$A$2:$H$9999,4,FALSE),"") | T19: =IFERROR(VLOOKUP(C19,'#level_value'!$A$2:$H$9999,7,FALSE),"") | U19: =IFERROR(VLOOKUP(C19,'#level_value'!$A$2:$H$9999,8,FALSE),"")
A20: =A19+1 -> 10019 | B20: =A20+10000 -> 20019 | C20: =B20+10000 -> 30019 | D20: ="SkillName."&A20 -> SkillName.10019 | E20: 라인드라이브 | F20: ="SkillDesc."&A20 -> SkillDesc.10019 | G20: 라인드라이브 타격시 타구속도 +{0}% | I20: Hitting | J20: =IFERROR(VLOOKUP(A20,'#level_value'!$A$2:$H$9999,3,FALSE),"") -> HittingSpeed | K20: =IFERROR(VLOOKUP(A20,'#level_value'!$A$2:$H$9999,4,FALSE),"") -> LinedriveHit | L20: =IFERROR(VLOOKUP(A20,'#level_value'!$A$2:$H$9999,7,FALSE),"") -> [0,0,0,0,0] | M20: =IFERROR(VLOOKUP(A20,'#level_value'!$A$2:$H$9999,8,FALSE),"") -> [30000,50000,70000,100000,150000] | N20: =IFERROR(VLOOKUP(B20,'#level_value'!$A$2:$H$9999,3,FALSE),"") | O20: =IFERROR(VLOOKUP(B20,'#level_value'!$A$2:$H$9999,4,FALSE),"") | P20: =IFERROR(VLOOKUP(B20,'#level_value'!$A$2:$H$9999,7,FALSE),"") | Q20: =IFERROR(VLOOKUP(B20,'#level_value'!$A$2:$H$9999,8,FALSE),"") | R20: =IFERROR(VLOOKUP(C20,'#level_value'!$A$2:$H$9999,3,FALSE),"") | S20: =IFERROR(VLOOKUP(C20,'#level_value'!$A$2:$H$9999,4,FALSE),"") | T20: =IFERROR(VLOOKUP(C20,'#level_value'!$A$2:$H$9999,7,FALSE),"") | U20: =IFERROR(VLOOKUP(C20,'#level_value'!$A$2:$H$9999,8,FALSE),"")
A21: =A20+1 -> 10020 | B21: =A21+10000 -> 20020 | C21: =B21+10000 -> 30020 | D21: ="SkillName."&A21 -> SkillName.10020 | E21: 플라이볼 | F21: ="SkillDesc."&A21 -> SkillDesc.10020 | G21: 플라이볼 타격시 타구속도 +{0}% | I21: Hitting | J21: =IFERROR(VLOOKUP(A21,'#level_value'!$A$2:$H$9999,3,FALSE),"") -> HittingSpeed | K21: =IFERROR(VLOOKUP(A21,'#level_value'!$A$2:$H$9999,4,FALSE),"") -> FlyHit | L21: =IFERROR(VLOOKUP(A21,'#level_value'!$A$2:$H$9999,7,FALSE),"") -> [0,0,0,0,0] | M21: =IFERROR(VLOOKUP(A21,'#level_value'!$A$2:$H$9999,8,FALSE),"") -> [30000,50000,70000,100000,150000] | N21: =IFERROR(VLOOKUP(B21,'#level_value'!$A$2:$H$9999,3,FALSE),"") | O21: =IFERROR(VLOOKUP(B21,'#level_value'!$A$2:$H$9999,4,FALSE),"") | P21: =IFERROR(VLOOKUP(B21,'#level_value'!$A$2:$H$9999,7,FALSE),"") | Q21: =IFERROR(VLOOKUP(B21,'#level_value'!$A$2:$H$9999,8,FALSE),"") | R21: =IFERROR(VLOOKUP(C21,'#level_value'!$A$2:$H$9999,3,FALSE),"") | S21: =IFERROR(VLOOKUP(C21,'#level_value'!$A$2:$H$9999,4,FALSE),"") | T21: =IFERROR(VLOOKUP(C21,'#level_value'!$A$2:$H$9999,7,FALSE),"") | U21: =IFERROR(VLOOKUP(C21,'#level_value'!$A$2:$H$9999,8,FALSE),"")
A22: =A21+1 -> 10021 | B22: =A22+10000 -> 20021 | C22: =B22+10000 -> 30021 | D22: ="SkillName."&A22 -> SkillName.10021 | E22: 히트앤드런 | F22: ="SkillDesc."&A22 -> SkillDesc.10021 | G22: 주자 도루 할 때 타격시 타구속도 +{0}% | I22: Hitting | J22: =IFERROR(VLOOKUP(A22,'#level_value'!$A$2:$H$9999,3,FALSE),"") -> HittingSpeed | K22: =IFERROR(VLOOKUP(A22,'#level_value'!$A$2:$H$9999,4,FALSE),"") -> RunAndHit | L22: =IFERROR(VLOOKUP(A22,'#level_value'!$A$2:$H$9999,7,FALSE),"") -> [0,0,0,0,0] | M22: =IFERROR(VLOOKUP(A22,'#level_value'!$A$2:$H$9999,8,FALSE),"") -> [30000,50000,70000,100000,150000] | N22: =IFERROR(VLOOKUP(B22,'#level_value'!$A$2:$H$9999,3,FALSE),"") | O22: =IFERROR(VLOOKUP(B22,'#level_value'!$A$2:$H$9999,4,FALSE),"") | P22: =IFERROR(VLOOKUP(B22,'#level_value'!$A$2:$H$9999,7,FALSE),"") | Q22: =IFERROR(VLOOKUP(B22,'#level_value'!$A$2:$H$9999,8,FALSE),"") | R22: =IFERROR(VLOOKUP(C22,'#level_value'!$A$2:$H$9999,3,FALSE),"") | S22: =IFERROR(VLOOKUP(C22,'#level_value'!$A$2:$H$9999,4,FALSE),"") | T22: =IFERROR(VLOOKUP(C22,'#level_value'!$A$2:$H$9999,7,FALSE),"") | U22: =IFERROR(VLOOKUP(C22,'#level_value'!$A$2:$H$9999,8,FALSE),"")
A23: =A22+1 -> 10022 | B23: =A23+10000 -> 20022 | C23: =B23+10000 -> 30022 | D23: ="SkillName."&A23 -> SkillName.10022 | E23: 홈경기 | F23: ="SkillDesc."&A23 -> SkillDesc.10022 | G23: 홈경기 시 컨택+{0} | I23: Hitting | J23: =IFERROR(VLOOKUP(A23,'#level_value'!$A$2:$H$9999,3,FALSE),"") -> Contact | K23: =IFERROR(VLOOKUP(A23,'#level_value'!$A$2:$H$9999,4,FALSE),"") -> HomeMatch | L23: =IFERROR(VLOOKUP(A23,'#level_value'!$A$2:$H$9999,7,FALSE),"") -> [0,0,0,0,0] | M23: =IFERROR(VLOOKUP(A23,'#level_value'!$A$2:$H$9999,8,FALSE),"") -> [5,8,14,20,30] | N23: =IFERROR(VLOOKUP(B23,'#level_value'!$A$2:$H$9999,3,FALSE),"") | O23: =IFERROR(VLOOKUP(B23,'#level_value'!$A$2:$H$9999,4,FALSE),"") | P23: =IFERROR(VLOOKUP(B23,'#level_value'!$A$2:$H$9999,7,FALSE),"") | Q23: =IFERROR(VLOOKUP(B23,'#level_value'!$A$2:$H$9999,8,FALSE),"") | R23: =IFERROR(VLOOKUP(C23,'#level_value'!$A$2:$H$9999,3,FALSE),"") | S23: =IFERROR(VLOOKUP(C23,'#level_value'!$A$2:$H$9999,4,FALSE),"") | T23: =IFERROR(VLOOKUP(C23,'#level_value'!$A$2:$H$9999,7,FALSE),"") | U23: =IFERROR(VLOOKUP(C23,'#level_value'!$A$2:$H$9999,8,FALSE),"")
A24: =A23+1 -> 10023 | B24: =A24+10000 -> 20023 | C24: =B24+10000 -> 30023 | D24: ="SkillName."&A24 -> SkillName.10023 | E24: 원정경기 | F24: ="SkillDesc."&A24 -> SkillDesc.10023 | G24: 원정경기 시 파워+{0} | I24: Hitting | J24: =IFERROR(VLOOKUP(A24,'#level_value'!$A$2:$H$9999,3,FALSE),"") -> Power | K24: =IFERROR(VLOOKUP(A24,'#level_value'!$A$2:$H$9999,4,FALSE),"") -> AwayMatch | L24: =IFERROR(VLOOKUP(A24,'#level_value'!$A$2:$H$9999,7,FALSE),"") -> [0,0,0,0,0] | M24: =IFERROR(VLOOKUP(A24,'#level_value'!$A$2:$H$9999,8,FALSE),"") -> [5,8,14,20,30] | N24: =IFERROR(VLOOKUP(B24,'#level_value'!$A$2:$H$9999,3,FALSE),"") | O24: =IFERROR(VLOOKUP(B24,'#level_value'!$A$2:$H$9999,4,FALSE),"") | P24: =IFERROR(VLOOKUP(B24,'#level_value'!$A$2:$H$9999,7,FALSE),"") | Q24: =IFERROR(VLOOKUP(B24,'#level_value'!$A$2:$H$9999,8,FALSE),"") | R24: =IFERROR(VLOOKUP(C24,'#level_value'!$A$2:$H$9999,3,FALSE),"") | S24: =IFERROR(VLOOKUP(C24,'#level_value'!$A$2:$H$9999,4,FALSE),"") | T24: =IFERROR(VLOOKUP(C24,'#level_value'!$A$2:$H$9999,7,FALSE),"") | U24: =IFERROR(VLOOKUP(C24,'#level_value'!$A$2:$H$9999,8,FALSE),"")
A25: =A24+1 -> 10024 | B25: =A25+10000 -> 20024 | C25: =B25+10000 -> 30024 | D25: ="SkillName."&A25 -> SkillName.10024 | E25: 낮경기 | F25: ="SkillDesc."&A25 -> SkillDesc.10024 | G25: 낮경기 시 선구+{0} 파워+{0} | I25: Hitting | J25: =IFERROR(VLOOKUP(A25,'#level_value'!$A$2:$H$9999,3,FALSE),"") -> Vision | K25: =IFERROR(VLOOKUP(A25,'#level_value'!$A$2:$H$9999,4,FALSE),"") -> DayMatch | L25: =IFERROR(VLOOKUP(A25,'#level_value'!$A$2:$H$9999,7,FALSE),"") -> [0,0,0,0,0] | M25: =IFERROR(VLOOKUP(A25,'#level_value'!$A$2:$H$9999,8,FALSE),"") -> [3,4,7,10,15] | N25: =IFERROR(VLOOKUP(B25,'#level_value'!$A$2:$H$9999,3,FALSE),"") -> Power | O25: =IFERROR(VLOOKUP(B25,'#level_value'!$A$2:$H$9999,4,FALSE),"") -> MainActivated | P25: =IFERROR(VLOOKUP(B25,'#level_value'!$A$2:$H$9999,7,FALSE),"") -> [0,0,0,0,0] | Q25: =IFERROR(VLOOKUP(B25,'#level_value'!$A$2:$H$9999,8,FALSE),"") -> [3,4,7,10,15] | R25: =IFERROR(VLOOKUP(C25,'#level_value'!$A$2:$H$9999,3,FALSE),"") | S25: =IFERROR(VLOOKUP(C25,'#level_value'!$A$2:$H$9999,4,FALSE),"") | T25: =IFERROR(VLOOKUP(C25,'#level_value'!$A$2:$H$9999,7,FALSE),"") | U25: =IFERROR(VLOOKUP(C25,'#level_value'!$A$2:$H$9999,8,FALSE),"")
A26: =A25+1 -> 10025 | B26: =A26+10000 -> 20025 | C26: =B26+10000 -> 30025 | D26: ="SkillName."&A26 -> SkillName.10025 | E26: 밤경기 | F26: ="SkillDesc."&A26 -> SkillDesc.10025 | G26: 밤경기 시 선구+{0} 컨택+{0} | I26: Hitting | J26: =IFERROR(VLOOKUP(A26,'#level_value'!$A$2:$H$9999,3,FALSE),"") -> Vision | K26: =IFERROR(VLOOKUP(A26,'#level_value'!$A$2:$H$9999,4,FALSE),"") -> NightMatch | L26: =IFERROR(VLOOKUP(A26,'#level_value'!$A$2:$H$9999,7,FALSE),"") -> [0,0,0,0,0] | M26: =IFERROR(VLOOKUP(A26,'#level_value'!$A$2:$H$9999,8,FALSE),"") -> [3,4,7,10,15] | N26: =IFERROR(VLOOKUP(B26,'#level_value'!$A$2:$H$9999,3,FALSE),"") -> Contact | O26: =IFERROR(VLOOKUP(B26,'#level_value'!$A$2:$H$9999,4,FALSE),"") -> MainActivated | P26: =IFERROR(VLOOKUP(B26,'#level_value'!$A$2:$H$9999,7,FALSE),"") -> [0,0,0,0,0] | Q26: =IFERROR(VLOOKUP(B26,'#level_value'!$A$2:$H$9999,8,FALSE),"") -> [3,4,7,10,15] | R26: =IFERROR(VLOOKUP(C26,'#level_value'!$A$2:$H$9999,3,FALSE),"") | S26: =IFERROR(VLOOKUP(C26,'#level_value'!$A$2:$H$9999,4,FALSE),"") | T26: =IFERROR(VLOOKUP(C26,'#level_value'!$A$2:$H$9999,7,FALSE),"") | U26: =IFERROR(VLOOKUP(C26,'#level_value'!$A$2:$H$9999,8,FALSE),"")
A27: =A26+1 -> 10026 | B27: =A27+10000 -> 20026 | C27: =B27+10000 -> 30026 | D27: ="SkillName."&A27 -> SkillName.10026 | E27: 서브마린킬러 | F27: ="SkillDesc."&A27 -> SkillDesc.10026 | G27: 언더핸드 투수 시 컨택+{0} | I27: Hitting | J27: =IFERROR(VLOOKUP(A27,'#level_value'!$A$2:$H$9999,3,FALSE),"") -> Contact | K27: =IFERROR(VLOOKUP(A27,'#level_value'!$A$2:$H$9999,4,FALSE),"") -> UnderPitcher | L27: =IFERROR(VLOOKUP(A27,'#level_value'!$A$2:$H$9999,7,FALSE),"") -> [30,35,40,45,50] | M27: =IFERROR(VLOOKUP(A27,'#level_value'!$A$2:$H$9999,8,FALSE),"") -> [5,8,14,20,30] | N27: =IFERROR(VLOOKUP(B27,'#level_value'!$A$2:$H$9999,3,FALSE),"") | O27: =IFERROR(VLOOKUP(B27,'#level_value'!$A$2:$H$9999,4,FALSE),"") | P27: =IFERROR(VLOOKUP(B27,'#level_value'!$A$2:$H$9999,7,FALSE),"") | Q27: =IFERROR(VLOOKUP(B27,'#level_value'!$A$2:$H$9999,8,FALSE),"") | R27: =IFERROR(VLOOKUP(C27,'#level_value'!$A$2:$H$9999,3,FALSE),"") | S27: =IFERROR(VLOOKUP(C27,'#level_value'!$A$2:$H$9999,4,FALSE),"") | T27: =IFERROR(VLOOKUP(C27,'#level_value'!$A$2:$H$9999,7,FALSE),"") | U27: =IFERROR(VLOOKUP(C27,'#level_value'!$A$2:$H$9999,8,FALSE),"")
A28: =A27+1 -> 10027 | B28: =A28+10000 -> 20027 | C28: =B28+10000 -> 30027 | D28: ="SkillName."&A28 -> SkillName.10027 | E28: 강심장1 | F28: ="SkillDesc."&A28 -> SkillDesc.10027 | G28: 투아웃에서 {0}%확률로 컨택 +{0} | I28: Hitting | J28: =IFERROR(VLOOKUP(A28,'#level_value'!$A$2:$H$9999,3,FALSE),"") -> Contact | K28: =IFERROR(VLOOKUP(A28,'#level_value'!$A$2:$H$9999,4,FALSE),"") -> TwoOut | L28: =IFERROR(VLOOKUP(A28,'#level_value'!$A$2:$H$9999,7,FALSE),"") -> [30,35,40,45,50] | M28: =IFERROR(VLOOKUP(A28,'#level_value'!$A$2:$H$9999,8,FALSE),"") -> [5,8,14,20,30] | N28: =IFERROR(VLOOKUP(B28,'#level_value'!$A$2:$H$9999,3,FALSE),"") | O28: =IFERROR(VLOOKUP(B28,'#level_value'!$A$2:$H$9999,4,FALSE),"") | P28: =IFERROR(VLOOKUP(B28,'#level_value'!$A$2:$H$9999,7,FALSE),"") | Q28: =IFERROR(VLOOKUP(B28,'#level_value'!$A$2:$H$9999,8,FALSE),"") | R28: =IFERROR(VLOOKUP(C28,'#level_value'!$A$2:$H$9999,3,FALSE),"") | S28: =IFERROR(VLOOKUP(C28,'#level_value'!$A$2:$H$9999,4,FALSE),"") | T28: =IFERROR(VLOOKUP(C28,'#level_value'!$A$2:$H$9999,7,FALSE),"") | U28: =IFERROR(VLOOKUP(C28,'#level_value'!$A$2:$H$9999,8,FALSE),"")
A29: =A28+1 -> 10028 | B29: =A29+10000 -> 20028 | C29: =B29+10000 -> 30028 | D29: ="SkillName."&A29 -> SkillName.10028 | E29: 강심장2 | F29: ="SkillDesc."&A29 -> SkillDesc.10028 | G29: 투아웃에서 {0}%확률로 컨택 +{0} | I29: Hitting | J29: =IFERROR(VLOOKUP(A29,'#level_value'!$A$2:$H$9999,3,FALSE),"") -> Contact | K29: =IFERROR(VLOOKUP(A29,'#level_value'!$A$2:$H$9999,4,FALSE),"") -> TwoOut | L29: =IFERROR(VLOOKUP(A29,'#level_value'!$A$2:$H$9999,7,FALSE),"") -> [50,55,60,65,70] | M29: =IFERROR(VLOOKUP(A29,'#level_value'!$A$2:$H$9999,8,FALSE),"") -> [10,16,22,34,50] | N29: =IFERROR(VLOOKUP(B29,'#level_value'!$A$2:$H$9999,3,FALSE),"") | O29: =IFERROR(VLOOKUP(B29,'#level_value'!$A$2:$H$9999,4,FALSE),"") | P29: =IFERROR(VLOOKUP(B29,'#level_value'!$A$2:$H$9999,7,FALSE),"") | Q29: =IFERROR(VLOOKUP(B29,'#level_value'!$A$2:$H$9999,8,FALSE),"") | R29: =IFERROR(VLOOKUP(C29,'#level_value'!$A$2:$H$9999,3,FALSE),"") | S29: =IFERROR(VLOOKUP(C29,'#level_value'!$A$2:$H$9999,4,FALSE),"") | T29: =IFERROR(VLOOKUP(C29,'#level_value'!$A$2:$H$9999,7,FALSE),"") | U29: =IFERROR(VLOOKUP(C29,'#level_value'!$A$2:$H$9999,8,FALSE),"")
A30: =A29+1 -> 10029 | B30: =A30+10000 -> 20029 | C30: =B30+10000 -> 30029 | D30: ="SkillName."&A30 -> SkillName.10029 | E30: 강심장3 | F30: ="SkillDesc."&A30 -> SkillDesc.10029 | G30: 투아웃에서 100%확률로 컨택 +{0}, 선구+{0} | I30: Hitting | J30: =IFERROR(VLOOKUP(A30,'#level_value'!$A$2:$H$9999,3,FALSE),"") -> Contact | K30: =IFERROR(VLOOKUP(A30,'#level_value'!$A$2:$H$9999,4,FALSE),"") -> TwoOut | L30: =IFERROR(VLOOKUP(A30,'#level_value'!$A$2:$H$9999,7,FALSE),"") -> [0,0,0,0,0] | M30: =IFERROR(VLOOKUP(A30,'#level_value'!$A$2:$H$9999,8,FALSE),"") -> [10,16,22,34,50] | N30: =IFERROR(VLOOKUP(B30,'#level_value'!$A$2:$H$9999,3,FALSE),"") -> Vision | O30: =IFERROR(VLOOKUP(B30,'#level_value'!$A$2:$H$9999,4,FALSE),"") -> MainActivated | P30: =IFERROR(VLOOKUP(B30,'#level_value'!$A$2:$H$9999,7,FALSE),"") -> [0,0,0,0,0] | Q30: =IFERROR(VLOOKUP(B30,'#level_value'!$A$2:$H$9999,8,FALSE),"") -> [5,8,11,18,25] | R30: =IFERROR(VLOOKUP(C30,'#level_value'!$A$2:$H$9999,3,FALSE),"") | S30: =IFERROR(VLOOKUP(C30,'#level_value'!$A$2:$H$9999,4,FALSE),"") | T30: =IFERROR(VLOOKUP(C30,'#level_value'!$A$2:$H$9999,7,FALSE),"") | U30: =IFERROR(VLOOKUP(C30,'#level_value'!$A$2:$H$9999,8,FALSE),"")
... A47: =A46+1 -> 10046 | B47: =A47+10000 -> 20046 | C47: =B47+10000 -> 30046 | D47: ="SkillName."&A47 -> SkillName.10046 | E47: 주자없음3 | F47: ="SkillDesc."&A47 -> SkillDesc.10046 | G47: 주자 없는 경우 100%확률로 선구 +{0}, 타구속도 +{0}% | I47: Hitting | J47: =IFERROR(VLOOKUP(A47,'#level_value'!$A$2:$H$9999,3,FALSE),"") -> Vision | K47: =IFERROR(VLOOKUP(A47,'#level_value'!$A$2:$H$9999,4,FALSE),"") -> NoRunner | L47: =IFERROR(VLOOKUP(A47,'#level_value'!$A$2:$H$9999,7,FALSE),"") -> [0,0,0,0,0] | M47: =IFERROR(VLOOKUP(A47,'#level_value'!$A$2:$H$9999,8,FALSE),"") -> [10,16,22,34,50] | N47: =IFERROR(VLOOKUP(B47,'#level_value'!$A$2:$H$9999,3,FALSE),"") -> HittingSpeed | O47: =IFERROR(VLOOKUP(B47,'#level_value'!$A$2:$H$9999,4,FALSE),"") -> MainActivated | P47: =IFERROR(VLOOKUP(B47,'#level_value'!$A$2:$H$9999,7,FALSE),"") -> [0,0,0,0,0] | Q47: =IFERROR(VLOOKUP(B47,'#level_value'!$A$2:$H$9999,8,FALSE),"") -> [30000,50000,70000,100000,150000] | R47: =IFERROR(VLOOKUP(C47,'#level_value'!$A$2:$H$9999,3,FALSE),"") | S47: =IFERROR(VLOOKUP(C47,'#level_value'!$A$2:$H$9999,4,FALSE),"") | T47: =IFERROR(VLOOKUP(C47,'#level_value'!$A$2:$H$9999,7,FALSE),"") | U47: =IFERROR(VLOOKUP(C47,'#level_value'!$A$2:$H$9999,8,FALSE),"")
A48: 10101 | B48: =A48+10000 -> 20101 | C48: =B48+10000 -> 30101 | D48: ="SkillName."&A48 -> SkillName.10101 | E48: 분노맨G1 | F48: ="SkillDesc."&A48 -> SkillDesc.10101 | G48: 아웃시 게이지가 쌓이고 차지 완료 후 발동시 파워+{0}, 컨택 +{0}, 선구+{0} | I48: Special | J48: =IFERROR(VLOOKUP(A48,'#level_value'!$A$2:$H$9999,3,FALSE),"") -> AllHitting | K48: =IFERROR(VLOOKUP(A48,'#level_value'!$A$2:$H$9999,4,FALSE),"") -> ResultOut | L48: =IFERROR(VLOOKUP(A48,'#level_value'!$A$2:$H$9999,7,FALSE),"") -> [0,0,0,0,0] | M48: =IFERROR(VLOOKUP(A48,'#level_value'!$A$2:$H$9999,8,FALSE),"") -> [5,8,14,20,30] | N48: =IFERROR(VLOOKUP(B48,'#level_value'!$A$2:$H$9999,3,FALSE),"") | O48: =IFERROR(VLOOKUP(B48,'#level_value'!$A$2:$H$9999,4,FALSE),"") | P48: =IFERROR(VLOOKUP(B48,'#level_value'!$A$2:$H$9999,7,FALSE),"") | Q48: =IFERROR(VLOOKUP(B48,'#level_value'!$A$2:$H$9999,8,FALSE),"") | R48: =IFERROR(VLOOKUP(C48,'#level_value'!$A$2:$H$9999,3,FALSE),"") | S48: =IFERROR(VLOOKUP(C48,'#level_value'!$A$2:$H$9999,4,FALSE),"") | T48: =IFERROR(VLOOKUP(C48,'#level_value'!$A$2:$H$9999,7,FALSE),"") | U48: =IFERROR(VLOOKUP(C48,'#level_value'!$A$2:$H$9999,8,FALSE),"")
A49: =A48+1 -> 10102 | B49: =A49+10000 -> 20102 | C49: =B49+10000 -> 30102 | D49: ="SkillName."&A49 -> SkillName.10102 | E49: 분노맨G2 | F49: ="SkillDesc."&A49 -> SkillDesc.10102 | G49: 아웃시 게이지가 쌓이고 차지 완료 후 발동시 파워+{0}, 컨택 +{0}, 선구+{0} | I49: Special | J49: =IFERROR(VLOOKUP(A49,'#level_value'!$A$2:$H$9999,3,FALSE),"") -> AllHitting | K49: =IFERROR(VLOOKUP(A49,'#level_value'!$A$2:$H$9999,4,FALSE),"") -> ResultOut | L49: =IFERROR(VLOOKUP(A49,'#level_value'!$A$2:$H$9999,7,FALSE),"") -> [0,0,0,0,0] | M49: =IFERROR(VLOOKUP(A49,'#level_value'!$A$2:$H$9999,8,FALSE),"") -> [10,16,22,34,50] | N49: =IFERROR(VLOOKUP(B49,'#level_value'!$A$2:$H$9999,3,FALSE),"") | O49: =IFERROR(VLOOKUP(B49,'#level_value'!$A$2:$H$9999,4,FALSE),"") | P49: =IFERROR(VLOOKUP(B49,'#level_value'!$A$2:$H$9999,7,FALSE),"") | Q49: =IFERROR(VLOOKUP(B49,'#level_value'!$A$2:$H$9999,8,FALSE),"") | R49: =IFERROR(VLOOKUP(C49,'#level_value'!$A$2:$H$9999,3,FALSE),"") | S49: =IFERROR(VLOOKUP(C49,'#level_value'!$A$2:$H$9999,4,FALSE),"") | T49: =IFERROR(VLOOKUP(C49,'#level_value'!$A$2:$H$9999,7,FALSE),"") | U49: =IFERROR(VLOOKUP(C49,'#level_value'!$A$2:$H$9999,8,FALSE),"")
A50: =A49+1 -> 10103 | B50: =A50+10000 -> 20103 | C50: =B50+10000 -> 30103 | D50: ="SkillName."&A50 -> SkillName.10103 | E50: 분노맨G3 | F50: ="SkillDesc."&A50 -> SkillDesc.10103 | G50: 아웃시 게이지가 쌓이고 차지 완료 후 발동시 파워+{0}, 컨택 +{0}, 선구+{0} | I50: Special | J50: =IFERROR(VLOOKUP(A50,'#level_value'!$A$2:$H$9999,3,FALSE),"") -> AllHitting | K50: =IFERROR(VLOOKUP(A50,'#level_value'!$A$2:$H$9999,4,FALSE),"") -> ResultOut | L50: =IFERROR(VLOOKUP(A50,'#level_value'!$A$2:$H$9999,7,FALSE),"") -> [0,0,0,0,0] | M50: =IFERROR(VLOOKUP(A50,'#level_value'!$A$2:$H$9999,8,FALSE),"") -> [10,16,22,34,50] | N50: =IFERROR(VLOOKUP(B50,'#level_value'!$A$2:$H$9999,3,FALSE),"") | O50: =IFERROR(VLOOKUP(B50,'#level_value'!$A$2:$H$9999,4,FALSE),"") | P50: =IFERROR(VLOOKUP(B50,'#level_value'!$A$2:$H$9999,7,FALSE),"") | Q50: =IFERROR(VLOOKUP(B50,'#level_value'!$A$2:$H$9999,8,FALSE),"") | R50: =IFERROR(VLOOKUP(C50,'#level_value'!$A$2:$H$9999,3,FALSE),"") | S50: =IFERROR(VLOOKUP(C50,'#level_value'!$A$2:$H$9999,4,FALSE),"") | T50: =IFERROR(VLOOKUP(C50,'#level_value'!$A$2:$H$9999,7,FALSE),"") | U50: =IFERROR(VLOOKUP(C50,'#level_value'!$A$2:$H$9999,8,FALSE),"")
A51: =A50+1 -> 10104 | B51: =A51+10000 -> 20104 | C51: =B51+10000 -> 30104 | D51: ="SkillName."&A51 -> SkillName.10104 | E51: 분위기맨G1 | F51: ="SkillDesc."&A51 -> SkillDesc.10104 | G51: 안타시 게이지가 쌓이고 차지 완료 후 발동시 파워+{0}, 컨택 +{0}, 선구+{0} | I51: Special | J51: =IFERROR(VLOOKUP(A51,'#level_value'!$A$2:$H$9999,3,FALSE),"") -> AllHitting | K51: =IFERROR(VLOOKUP(A51,'#level_value'!$A$2:$H$9999,4,FALSE),"") -> ResultHit | L51: =IFERROR(VLOOKUP(A51,'#level_value'!$A$2:$H$9999,7,FALSE),"") -> [0,0,0,0,0] | M51: =IFERROR(VLOOKUP(A51,'#level_value'!$A$2:$H$9999,8,FALSE),"") -> [5,8,14,20,30] | N51: =IFERROR(VLOOKUP(B51,'#level_value'!$A$2:$H$9999,3,FALSE),"") | O51: =IFERROR(VLOOKUP(B51,'#level_value'!$A$2:$H$9999,4,FALSE),"") | P51: =IFERROR(VLOOKUP(B51,'#level_value'!$A$2:$H$9999,7,FALSE),"") | Q51: =IFERROR(VLOOKUP(B51,'#level_value'!$A$2:$H$9999,8,FALSE),"") | R51: =IFERROR(VLOOKUP(C51,'#level_value'!$A$2:$H$9999,3,FALSE),"") | S51: =IFERROR(VLOOKUP(C51,'#level_value'!$A$2:$H$9999,4,FALSE),"") | T51: =IFERROR(VLOOKUP(C51,'#level_value'!$A$2:$H$9999,7,FALSE),"") | U51: =IFERROR(VLOOKUP(C51,'#level_value'!$A$2:$H$9999,8,FALSE),"")
A52: =A51+1 -> 10105 | B52: =A52+10000 -> 20105 | C52: =B52+10000 -> 30105 | D52: ="SkillName."&A52 -> SkillName.10105 | E52: 분위기맨G2 | F52: ="SkillDesc."&A52 -> SkillDesc.10105 | G52: 안타시 게이지가 쌓이고 차지 완료 후 발동시 파워+{0}, 컨택 +{0}, 선구+{0} | I52: Special | J52: =IFERROR(VLOOKUP(A52,'#level_value'!$A$2:$H$9999,3,FALSE),"") -> AllHitting | K52: =IFERROR(VLOOKUP(A52,'#level_value'!$A$2:$H$9999,4,FALSE),"") -> ResultHit | L52: =IFERROR(VLOOKUP(A52,'#level_value'!$A$2:$H$9999,7,FALSE),"") -> [0,0,0,0,0] | M52: =IFERROR(VLOOKUP(A52,'#level_value'!$A$2:$H$9999,8,FALSE),"") -> [10,16,22,34,50] | N52: =IFERROR(VLOOKUP(B52,'#level_value'!$A$2:$H$9999,3,FALSE),"") | O52: =IFERROR(VLOOKUP(B52,'#level_value'!$A$2:$H$9999,4,FALSE),"") | P52: =IFERROR(VLOOKUP(B52,'#level_value'!$A$2:$H$9999,7,FALSE),"") | Q52: =IFERROR(VLOOKUP(B52,'#level_value'!$A$2:$H$9999,8,FALSE),"") | R52: =IFERROR(VLOOKUP(C52,'#level_value'!$A$2:$H$9999,3,FALSE),"") | S52: =IFERROR(VLOOKUP(C52,'#level_value'!$A$2:$H$9999,4,FALSE),"") | T52: =IFERROR(VLOOKUP(C52,'#level_value'!$A$2:$H$9999,7,FALSE),"") | U52: =IFERROR(VLOOKUP(C52,'#level_value'!$A$2:$H$9999,8,FALSE),"")
A53: =A52+1 -> 10106 | B53: =A53+10000 -> 20106 | C53: =B53+10000 -> 30106 | D53: ="SkillName."&A53 -> SkillName.10106 | E53: 분위기맨G3 | F53: ="SkillDesc."&A53 -> SkillDesc.10106 | G53: 안타시 게이지가 쌓이고 차지 완료 후 발동시 파워+{0}, 컨택 +{0}, 선구+{0} | I53: Special | J53: =IFERROR(VLOOKUP(A53,'#level_value'!$A$2:$H$9999,3,FALSE),"") -> AllHitting | K53: =IFERROR(VLOOKUP(A53,'#level_value'!$A$2:$H$9999,4,FALSE),"") -> ResultHit | L53: =IFERROR(VLOOKUP(A53,'#level_value'!$A$2:$H$9999,7,FALSE),"") -> [0,0,0,0,0] | M53: =IFERROR(VLOOKUP(A53,'#level_value'!$A$2:$H$9999,8,FALSE),"") -> [10,16,22,34,50] | N53: =IFERROR(VLOOKUP(B53,'#level_value'!$A$2:$H$9999,3,FALSE),"") | O53: =IFERROR(VLOOKUP(B53,'#level_value'!$A$2:$H$9999,4,FALSE),"") | P53: =IFERROR(VLOOKUP(B53,'#level_value'!$A$2:$H$9999,7,FALSE),"") | Q53: =IFERROR(VLOOKUP(B53,'#level_value'!$A$2:$H$9999,8,FALSE),"") | R53: =IFERROR(VLOOKUP(C53,'#level_value'!$A$2:$H$9999,3,FALSE),"") | S53: =IFERROR(VLOOKUP(C53,'#level_value'!$A$2:$H$9999,4,FALSE),"") | T53: =IFERROR(VLOOKUP(C53,'#level_value'!$A$2:$H$9999,7,FALSE),"") | U53: =IFERROR(VLOOKUP(C53,'#level_value'!$A$2:$H$9999,8,FALSE),"")
A54: =A53+1 -> 10107 | B54: =A54+10000 -> 20107 | C54: =B54+10000 -> 30107 | D54: ="SkillName."&A54 -> SkillName.10107 | E54: 불안감G1 | F54: ="SkillDesc."&A54 -> SkillDesc.10107 | G54: 지고있는경우 게이지가 쌓이고 차지 완료 후 발동시 파워+{0}, 컨택 +{0}, 선구+{0} | I54: Special | J54: =IFERROR(VLOOKUP(A54,'#level_value'!$A$2:$H$9999,3,FALSE),"") -> AllHitting | K54: =IFERROR(VLOOKUP(A54,'#level_value'!$A$2:$H$9999,4,FALSE),"") -> Losing1 | L54: =IFERROR(VLOOKUP(A54,'#level_value'!$A$2:$H$9999,7,FALSE),"") -> [0,0,0,0,0] | M54: =IFERROR(VLOOKUP(A54,'#level_value'!$A$2:$H$9999,8,FALSE),"") -> [5,8,14,20,30] | N54: =IFERROR(VLOOKUP(B54,'#level_value'!$A$2:$H$9999,3,FALSE),"") | O54: =IFERROR(VLOOKUP(B54,'#level_value'!$A$2:$H$9999,4,FALSE),"") | P54: =IFERROR(VLOOKUP(B54,'#level_value'!$A$2:$H$9999,7,FALSE),"") | Q54: =IFERROR(VLOOKUP(B54,'#level_value'!$A$2:$H$9999,8,FALSE),"") | R54: =IFERROR(VLOOKUP(C54,'#level_value'!$A$2:$H$9999,3,FALSE),"") | S54: =IFERROR(VLOOKUP(C54,'#level_value'!$A$2:$H$9999,4,FALSE),"") | T54: =IFERROR(VLOOKUP(C54,'#level_value'!$A$2:$H$9999,7,FALSE),"") | U54: =IFERROR(VLOOKUP(C54,'#level_value'!$A$2:$H$9999,8,FALSE),"")
A55: =A54+1 -> 10108 | B55: =A55+10000 -> 20108 | C55: =B55+10000 -> 30108 | D55: ="SkillName."&A55 -> SkillName.10108 | E55: 불안감G2 | F55: ="SkillDesc."&A55 -> SkillDesc.10108 | G55: 지고있는경우 게이지가 쌓이고 차지 완료 후 발동시 파워+{0}, 컨택 +{0}, 선구+{0} | I55: Special | J55: =IFERROR(VLOOKUP(A55,'#level_value'!$A$2:$H$9999,3,FALSE),"") -> AllHitting | K55: =IFERROR(VLOOKUP(A55,'#level_value'!$A$2:$H$9999,4,FALSE),"") -> Losing1 | L55: =IFERROR(VLOOKUP(A55,'#level_value'!$A$2:$H$9999,7,FALSE),"") -> [0,0,0,0,0] | M55: =IFERROR(VLOOKUP(A55,'#level_value'!$A$2:$H$9999,8,FALSE),"") -> [10,16,22,34,50] | N55: =IFERROR(VLOOKUP(B55,'#level_value'!$A$2:$H$9999,3,FALSE),"") | O55: =IFERROR(VLOOKUP(B55,'#level_value'!$A$2:$H$9999,4,FALSE),"") | P55: =IFERROR(VLOOKUP(B55,'#level_value'!$A$2:$H$9999,7,FALSE),"") | Q55: =IFERROR(VLOOKUP(B55,'#level_value'!$A$2:$H$9999,8,FALSE),"") | R55: =IFERROR(VLOOKUP(C55,'#level_value'!$A$2:$H$9999,3,FALSE),"") | S55: =IFERROR(VLOOKUP(C55,'#level_value'!$A$2:$H$9999,4,FALSE),"") | T55: =IFERROR(VLOOKUP(C55,'#level_value'!$A$2:$H$9999,7,FALSE),"") | U55: =IFERROR(VLOOKUP(C55,'#level_value'!$A$2:$H$9999,8,FALSE),"")
A56: =A55+1 -> 10109 | B56: =A56+10000 -> 20109 | C56: =B56+10000 -> 30109 | D56: ="SkillName."&A56 -> SkillName.10109 | E56: 불안감G3 | F56: ="SkillDesc."&A56 -> SkillDesc.10109 | G56: 지고있는경우 게이지가 쌓이고 차지 완료 후 발동시 파워+{0}, 컨택 +{0}, 선구+{0} | I56: Special | J56: =IFERROR(VLOOKUP(A56,'#level_value'!$A$2:$H$9999,3,FALSE),"") -> AllHitting | K56: =IFERROR(VLOOKUP(A56,'#level_value'!$A$2:$H$9999,4,FALSE),"") -> Losing1 | L56: =IFERROR(VLOOKUP(A56,'#level_value'!$A$2:$H$9999,7,FALSE),"") -> [0,0,0,0,0] | M56: =IFERROR(VLOOKUP(A56,'#level_value'!$A$2:$H$9999,8,FALSE),"") -> [10,16,22,34,50] | N56: =IFERROR(VLOOKUP(B56,'#level_value'!$A$2:$H$9999,3,FALSE),"") | O56: =IFERROR(VLOOKUP(B56,'#level_value'!$A$2:$H$9999,4,FALSE),"") | P56: =IFERROR(VLOOKUP(B56,'#level_value'!$A$2:$H$9999,7,FALSE),"") | Q56: =IFERROR(VLOOKUP(B56,'#level_value'!$A$2:$H$9999,8,FALSE),"") | R56: =IFERROR(VLOOKUP(C56,'#level_value'!$A$2:$H$9999,3,FALSE),"") | S56: =IFERROR(VLOOKUP(C56,'#level_value'!$A$2:$H$9999,4,FALSE),"") | T56: =IFERROR(VLOOKUP(C56,'#level_value'!$A$2:$H$9999,7,FALSE),"") | U56: =IFERROR(VLOOKUP(C56,'#level_value'!$A$2:$H$9999,8,FALSE),"")
...

Sheet #level_value
A1: ="# 스킬 idx " &A3& VLOOKUP(A3,SkillData!A$2:E$459,3,FALSE) -> # 스킬 idx 1000130001
A2: idx | B2: lv | C2: #Key | D2: #Condition | E2: Per | F2: Val
A3: 10001 | B3: 1 | C3: Vision | D3: Cumulative | E3: 0 | F3: 5 | G3: ="[" &E3&","&E4&","&E5&","&E6&","&E7& "]" -> [0,0,0,0,0] | H3: ="[" &F3&","&F4&","&F5&","&F6&","&F7& "]" -> [5,8,14,20,30]
B4: 2 | C4: Vision | D4: Cumulative | E4: 0 | F4: 8
B5: 3 | C5: Vision | D5: Cumulative | E5: 0 | F5: 14
B6: 4 | C6: Vision | D6: Cumulative | E6: 0 | F6: 20
B7: 5 | C7: Vision | D7: Cumulative | E7: 0 | F7: 30
A9: ="# 스킬 idx " &A11& VLOOKUP(A11,SkillData!A$2:E$459,3,FALSE) -> # 스킬 idx 1000230002
A10: idx | B10: lv | C10: #Key | D10: #Condition | E10: Per | F10: Val
A11: 10002 | B11: 1 | C11: Vision | D11: Cumulative | E11: 0 | F11: 10 | G11: ="[" &E11&","&E12&","&E13&","&E14&","&E15& "]" -> [0,0,0,0,0] | H11: ="[" &F11&","&F12&","&F13&","&F14&","&F15& "]" -> [10,16,22,34,50]
B12: 2 | C12: Vision | D12: Cumulative | E12: 0 | F12: 16
B13: 3 | C13: Vision | D13: Cumulative | E13: 0 | F13: 22
B14: 4 | C14: Vision | D14: Cumulative | E14: 0 | F14: 34
B15: 5 | C15: Vision | D15: Cumulative | E15: 0 | F15: 50
A17: ="# 스킬 idx " &A19& VLOOKUP(A19,SkillData!A$2:E$459,3,FALSE) -> # 스킬 idx 1000330003
A18: idx | B18: lv | C18: #Key | D18: #Condition | E18: Per | F18: Val
A19: 10003 | B19: 1 | C19: Vision | D19: Cumulative | E19: 0 | F19: 10 | G19: ="[" &E19&","&E20&","&E21&","&E22&","&E23& "]" -> [0,0,0,0,0] | H19: ="[" &F19&","&F20&","&F21&","&F22&","&F23& "]" -> [10,16,22,34,50]
B20: 2 | C20: Vision | D20: Cumulative | E20: 0 | F20: 16
B21: 3 | C21: Vision | D21: Cumulative | E21: 0 | F21: 22
B22: 4 | C22: Vision | D22: Cumulative | E22: 0 | F22: 34
B23: 5 | C23: Vision | D23: Cumulative | E23: 0 | F23: 50
A24: =A19+10000 -> 20003 | B24: 1 | C24: HittingSpeed | D24: AfterHit | E24: 0 | F24: 30000 | G24: ="[" &E24&","&E25&","&E26&","&E27&","&E28& "]" -> [0,0,0,0,0] | H24: ="[" &F24&","&F25&","&F26&","&F27&","&F28& "]" -> [30000,50000,70000,100000,150000]
B25: 2 | C25: HittingSpeed | D25: AfterHit | E25: 0 | F25: 50000
B26: 3 | C26: HittingSpeed | D26: AfterHit | E26: 0 | F26: 70000
B27: 4 | C27: HittingSpeed | D27: AfterHit | E27: 0 | F27: 100000
B28: 5 | C28: HittingSpeed | D28: AfterHit | E28: 0 | F28: 150000
A30: ="# 스킬 idx " &A32& VLOOKUP(A32,SkillData!A$2:E$459,3,FALSE) -> # 스킬 idx 1000430004
A31: idx | B31: lv | C31: #Key | D31: #Condition | E31: Per | F31: Val
A32: 10004 | B32: 1 | C32: Contact | D32: RightPitcher | E32: 30 | F32: 5 | G32: ="[" &E32&","&E33&","&E34&","&E35&","&E36& "]" -> [30,35,40,45,50] | H32: ="[" &F32&","&F33&","&F34&","&F35&","&F36& "]" -> [5,8,14,20,30]
B33: 2 | C33: Contact | D33: RightPitcher | E33: 35 | F33: 8
B34: 3 | C34: Contact | D34: RightPitcher | E34: 40 | F34: 14
B35: 4 | C35: Contact | D35: RightPitcher | E35: 45 | F35: 20
B36: 5 | C36: Contact | D36: RightPitcher | E36: 50 | F36: 30
A38: ="# 스킬 idx " &A40& VLOOKUP(A40,SkillData!A$2:E$459,3,FALSE) -> # 스킬 idx 1000530005
A39: idx | B39: lv | C39: #Key | D39: #Condition | E39: Per | F39: Val
A40: 10005 | B40: 1 | C40: Contact | D40: RightPitcher | E40: 50 | F40: 10 | G40: ="[" &E40&","&E41&","&E42&","&E43&","&E44& "]" -> [50,55,60,65,70] | H40: ="[" &F40&","&F41&","&F42&","&F43&","&F44& "]" -> [10,16,22,34,50]
B41: 2 | C41: Contact | D41: RightPitcher | E41: 55 | F41: 16
B42: 3 | C42: Contact | D42: RightPitcher | E42: 60 | F42: 22
B43: 4 | C43: Contact | D43: RightPitcher | E43: 65 | F43: 34
B44: 5 | C44: Contact | D44: RightPitcher | E44: 70 | F44: 50
...

Sheet #조건테이블
A7: #KOBSkillCondition 스킬조건 | E7: #KOBSkillKey 스킬키 | I7: #KOBSkillType | M7: #KOBRarity
A8: NoCondition | B8: 1 | E8: Power | F8: 1 | I8: Hitting | J8: 1 | M8: COMMON | N8: 1
A9: Cumulative | B9: 2 | E9: Contact | F9: 2 | I9: Pysical | J9: 2 | M9: RARE | N9: 2
A10: RightPitcher | B10: 3 | E10: Vision | F10: 3 | I10: Special | J10: 3 | M10: EPIC | N10: 3
A11: LeftPitcher | B11: 4 | E11: Fielding | F11: 4 | I11: Wide | J11: 4 | M11: LEGENDARY | N11: 4
A12: AfterHit | B12: 5 | E12: Throwing | F12: 5 | M12: BLACK | N12: 5
A13: MainActivated | B13: 6 | E13: Speed | F13: 6
A14: Walkoff | B14: 7 | E14: RunningSkill | F14: 7
A15: FirstPitch | B15: 8 | E15: HittingSpeed | F15: 8
A16: BreakballHit | B16: 9 | E16: CheckSwing | F16: 9 | G16: #체크스윙 별도
A17: FastballHit | B17: 10 | E17: AllHitting | F17: 10
A18: LinedriveHit | B18: 11 | E18: AllDefense | F18: 11
A19: FlyHit | B19: 12 | E19: FieldSkill | F19: 12
A20: RunAndHit | B20: 13 | E20: SkillGear | F20: 13 | G20: 장비장착시 스킬
A21: HomeMatch | B21: 14 | E21: InfieldDiving | F21: 14 | G21: #내야 다이빙 별도
A22: AwayMatch | B22: 15 | E22: OutFieldDiving | F22: 15 | G22: #외야 다이빙 별도
A23: DayMatch | B23: 16 | E23: TimingPlus | F23: 16 | G23: #타이밍 플러스 별도
A24: NightMatch | B24: 17
A25: UnderPitcher | B25: 18
A26: TwoOut | B26: 19
A27: TwoStrike | B27: 20
A28: Chance | B28: 21
A29: Losing1 | B29: 22
A30: Losing2 | B30: 23
A31: InningFirst | B31: 24
A32: FullBase | B32: 25
A33: Winning1 | B33: 26
A34: Winning2 | B34: 27
A35: NoRunner | B35: 28
... A53: Inning789 | B53: 46

Sheet 스킬구상
B1: idx | C1: 이름 | D1: 특징 | E1: 조건 | F1: 사용 방법 | G1: 주 능력 | H1: 추가 능력 (주능력의 반) | I1: 같이 넣으면 안되는 스킬 | J1: 추후 사긴선수시 이 제한 풀을것 | K1: 능력 | L1: 인게임에 적용되는 법 | M1: COMMON | N1: Rare | O1: Epic | P1: Legend
A2: hitting skill | B2: 10001 | C2: 집중력1 | E2: 3구부터 | G2: 선구 | I2: 초구 | K2: 선구 | L2: 선구 관련 | M2: 선구+ | N2: 공의 궤적 plus | O2: 체크스윙 plus | P2: 타이밍 plus
B3: =B2+1 -> 10002 | C3: 집중력2 | E3: 2구부터 | G3: 위와같음 | K3: 컨택 | L3: 컨택관련 | M3: 컨택+ | N3: 안타억제 Lv1 | O3: 안타억제 Lv2 | P3: 안타억제 Lv3
B4: =B3+1 -> 10003 | C4: 집중력3 | E4: 2구부터 | G4: 위와같음 | H4: 타구속도 | K4: 파워 | L4: 파워관련 | M4: 파워+ | N4: 홈런억제 Lv1 | O4: 홈런억제 Lv2 | P4: 홈런억제 Lv3
B5: =B4+1 -> 10004 | C5: 우완킬러1 | D5: 확률 30%부터 | E5: 오른손투수 | G5: 컨택 | I5: 좌완킬러 | K5: 타구속도 | L5: 타구속도 | O5: 타구속도UP
B6: =B5+1 -> 10005 | C6: 우완킬러2 | D6: 확률 50%부터 | E6: 오른손투수 | G6: 위와같음
B7: =B6+1 -> 10006 | C7: 우완킬러3 | D7: 확률 100%부터 | E7: 오른손투수 | G7: 위와같음 | H7: 선구
B8: =B7+1 -> 10007 | C8: 좌완킬러1 | D8: 확률 30%부터 | E8: 왼손투수 | G8: 파워 | I8: 우완킬러
B9: =B8+1 -> 10008 | C9: 좌완킬러2 | D9: 확률 50%부터 | E9: 왼손투수 | G9: 위와같음
B10: =B9+1 -> 10009 | C10: 좌완킬러3 | D10: 확률 100%부터 | E10: 왼손투수 | G10: 위와같음 | H10: 선구
B11: =B10+1 -> 10010 | C11: 끝내기 안타 | E11: 9회 | G11: 컨택
B12: =B11+1 -> 10011 | C12: 끝내기 홈런 | E12: 9회 | G12: 파워
B13: =B12+1 -> 10012 | C13: 초구1 | D13: 확률 30%부터 | E13: 초구 | G13: 파워 | I13: 집중력
B14: =B13+1 -> 10013 | C14: 초구2 | D14: 확률 50%부터 | G14: 위와같음
B15: =B14+1 -> 10014 | C15: 초구3 | D15: 확률 100%부터 | G15: 위와같음 | H15: 컨택
B16: =B15+1 -> 10015 | C16: 변화구1 | E16: 변화구 타격시 | G16: 타구속도 | I16: 직구
B17: =B16+1 -> 10016 | C17: 변화구2 | G17: 위와같음 | H17: 체크스윙 | K17: 선구
B18: =B17+1 -> 10017 | C18: 직구1 | E18: 직구 타격시 | G18: 타구속도 | I18: 변화구 | K18: 컨택
B19: =B18+1 -> 10018 | C19: 직구2 | G19: 위와같음 | H19: 체크스윙 | K19: 파워
B20: =B19+1 -> 10019 | C20: 라인드라이브 | G20: 타구속도 | I20: 플라이볼 | K20: 타구속도
B21: =B20+1 -> 10020 | C21: 플라이볼 | G21: 타구속도 | I21: 라인드라이브
B22: =B21+1 -> 10021 | C22: 히트앤드런 | G22: 타구속도
B23: =B22+1 -> 10022 | C23: 홈경기 | G23: 컨택 | I23: 원정경기
B24: =B23+1 -> 10023 | C24: 원정경기 | G24: 파워 | I24: 홈경기
B25: =B24+1 -> 10024 | C25: 낮경기 | G25: 선구 | H25: 파워 | I25: 밤경기
B26: =B25+1 -> 10025 | C26: 밤경기 | G26: 선구 | H26: 컨택 | I26: 낮경기
B27: =B26+1 -> 10026 | C27: 서브마린 킬러 | G27: 컨택
B28: =B27+1 -> 10027 | C28: 강심장1 | D28: 확률 30%부터 | E28: 투아웃에서 | G28: 컨택
B29: =B28+1 -> 10028 | C29: 강심장2 | D29: 확률 50%부터 | E29: 투아웃에서 | G29: 위와같음
B30: =B29+1 -> 10029 | C30: 강심장3 | D30: 확률 100%부터 | E30: 투아웃에서 | G30: 위와같음 | H30: 선구
B31: =B30+1 -> 10030 | C31: 투스트라이크1 | D31: 확률 30%부터 | E31: 투스트라이크시 | G31: 선구
B32: =B31+1 -> 10031 | C32: 투스트라이크2 | D32: 확률 50%부터 | E32: 투스트라이크시 | G32: 위와같음
B33: =B32+1 -> 10032 | C33: 투스트라이크3 | D33: 확률 100%부터 | E33: 투스트라이크시 | G33: 위와같음 | H33: 체크스윙
B34: =B33+1 -> 10033 | C34: 찬스1 | D34: 확률 30%부터 | G34: 파워 | I34: 주자없음
B35: =B34+1 -> 10034 | C35: 찬스2 | D35: 확률 50%부터 | G35: 위와같음
B36: =B35+1 -> 10035 | C36: 찬스3 | D36: 확률 100%부터 | G36: 위와같음 | H36: 컨택 | K36: 능력치 | L36: 사용스
B37: =B36+1 -> 10036 | C37: 언더독 Type1 | E37: 지고 있을때 | G37: 컨택 | I37: 영양가 | K37: 주파워 | L37: =COUNTIF($G$2:$G$47,"파워") -> 6
B38: =B37+1 -> 10037 | C38: 언더독 Type2 | E38: 크게 지고 있을 때 | G38: 위와같음 | K38: 주컨택 | L38: =COUNTIF($G$2:$G$47,"컨택") -> 6
B39: =B38+1 -> 10038 | C39: 이닝 첫타자1 | D39: 확률 30%부터 | G39: 선구 | K39: 주선구 | L39: =COUNTIF($G$2:$G$47,"선구") -> 6
B40: =B39+1 -> 10039 | C40: 이닝 첫타자2 | D40: 확률 50%부터 | G40: 위와같음 | K40: 주타구속도 | L40: =COUNTIF($G$2:$G$47,"타구속도") -> 6
...

Sheet Enum
A4: #KOBRarity | D4: #KOBHand | G4: #PlayingType | J4: #CharacterType | M4: #KOBPosition | P4: #KOBBody | S4: #KOBSlotType | V4: #SKILL | X4: 관여 능력 | Z4: #Gear | AB4: 관여 능력
A5: COMMON | B5: 1 | D5: Left | E5: 0 | G5: None | H5: 0 | J5: Ballers | K5: 1 | M5: Pitcher | N5: 1 | P5: Normal | Q5: 1 | S5: None | T5: 0 | V5: 집중력1 | W5: 10001 | X5: 선구 | Z5: 글러브1 | AA5: 20001 | AB5: 수비
A6: RARE | B6: 2 | D6: Right | E6: 1 | G6: WellRoundedHitter | H6: 1 | J6: Pitcher | K6: 2 | M6: Catcher | N6: 2 | P6: Fat | Q6: 2 | S6: HittingSkill | T6: 1 | V6: 집중력2 | W6: =W5+1 -> 10002 | X6: 선구 | Z6: 글러브2 | AA6: =AA5+1 -> 20002 | AB6: 수비
A7: EPIC | B7: 3 | D7: Switch | E7: 2 | G7: PowerSlugger | H7: 2 | J7: MyHMan | K7: 3 | M7: First | N7: 3 | P7: Muscle | Q7: 3 | S7: PysicalSkill | T7: 2 | V7: 집중력3 | W7: =W6+1 -> 10003 | X7: 선구 | Z7: 글러브3 | AA7: =AA6+1 -> 20003 | AB7: 수비
A8: LEGENDARY | B8: 4 | G8: ProductiveHitter | H8: 3 | J8: MyHPitcher | K8: 4 | M8: Second | N8: 4 | P8: Girl | Q8: 4 | S8: Gear | T8: 11 | V8: 우완킬러1 | W8: =W7+1 -> 10004 | X8: 컨택 | Z8: 내야스킬글러브1 | AA8: =AA7+1 -> 20004 | AB8: 필드스킬
A9: BLACK | B9: 5 | G9: PrecisionHitter | H9: 4 | J9: HMan | K9: 5 | M9: Third | N9: 5 | P9: Special | Q9: 5 | V9: 우완킬러2 | W9: =W8+1 -> 10005 | X9: 컨택 | Z9: 외야스킬글러브2 | AA9: =AA8+1 -> 20005 | AB9: 필드스킬
G10: BaseRunningSpecialist | H10: 5 | J10: HPitcher | K10: 6 | M10: Short | N10: 6 | V10: 우완킬러3 | W10: =W9+1 -> 10006 | X10: 컨택 | Z10: 포수스킬글러브3 | AA10: =AA9+1 -> 20006 | AB10: 필드스킬
G11: DefensiveAce | H11: 6 | M11: Left | N11: 7 | V11: 좌완킬러1 | W11: =W10+1 -> 10007 | X11: 파워 | Z11: 스파이크1 | AA11: =AA10+1 -> 20007 | AB11: 주루
G12: Two_Way | H12: 100 | M12: Center | N12: 8 | V12: 좌완킬러2 | W12: =W11+1 -> 10008 | X12: 파워 | Z12: 스파이크2 | AA12: =AA11+1 -> 20008 | AB12: 주루
M13: Right | N13: 9 | V13: 좌완킬러3 | W13: =W12+1 -> 10009 | X13: 파워 | Z13: 스파이크3 | AA13: =AA12+1 -> 20009 | AB13: 주루
M14: DH | N14: 10 | V14: 끝내기안타 | W14: =W13+1 -> 10010 | X14: 컨택 | Z14: 스킬스파이크1 | AA14: =AA13+1 -> 20010 | AB14: 주루스킬
M15: InfieldUtil | N15: 11 | V15: 끝내기홈런 | W15: =W14+1 -> 10011 | X15: 파워 | Z15: 스킬스파이크2 | AA15: =AA14+1 -> 20011 | AB15: 주루스킬
M16: InfieldCatcherUtil | N16: 12 | V16: 초구1 | W16: =W15+1 -> 10012 | X16: 파워 | Z16: 스킬스파이크3 | AA16: =AA15+1 -> 20012 | AB16: 주루스킬
M17: OutfieldUtil | N17: 13 | V17: 초구2 | W17: =W16+1 -> 10013 | X17: 파워 | Z17: 헬멧1 | AA17: =AA16+1 -> 20013 | AB17: 선구
M18: OutfieldCatcherUtil | N18: 14 | V18: 초구3 | W18: =W17+1 -> 10014 | X18: 파워 | Z18: 헬멧2 | AA18: =AA17+1 -> 20014 | AB18: 선구
M19: InOutField | N19: 15 | V19: 변화구1 | W19: =W18+1 -> 10015 | X19: 타구속도 | Z19: 헬멧3 | AA19: =AA18+1 -> 20015 | AB19: 선구
M20: AllRounder | N20: 16 | V20: 변화구2 | W20: =W19+1 -> 10016 | X20: 타구속도 | Z20: 스킬 헬멧1 | AA20: =AA19+1 -> 20016 | AB20: 선구관련스킬
V21: 직구1 | W21: =W20+1 -> 10017 | X21: 타구속도 | Z21: 스킬 헬멧2 | AA21: =AA20+1 -> 20017 | AB21: 선구관련스킬
V22: 직구2 | W22: =W21+1 -> 10018 | X22: 타구속도 | Z22: 스킬 헬멧3 | AA22: =AA21+1 -> 20018 | AB22: 선구관련스킬
V23: 라인드라이브 | W23: =W22+1 -> 10019 | X23: 타구속도 | Z23: 언더셔츠1 | AA23: =AA22+1 -> 20019 | AB23: 송구
V24: 플라이볼 | W24: =W23+1 -> 10020 | X24: 타구속도 | Z24: 언더셔츠2 | AA24: =AA23+1 -> 20020 | AB24: 송구
V25: 히트앤드런 | W25: =W24+1 -> 10021 | X25: 타구속도 | Z25: 언더셔츠3 | AA25: =AA24+1 -> 20021 | AB25: 송구
V26: 홈경기 | W26: =W25+1 -> 10022 | X26: 컨택 | Z26: 스킬언더셔츠1 | AA26: =AA25+1 -> 20022 | AB26: 필드스킬
V27: 원정경기 | W27: =W26+1 -> 10023 | X27: 파워 | Z27: 스킬언더셔츠2 | AA27: =AA26+1 -> 20023 | AB27: 필드스킬
V28: 낮경기 | W28: =W27+1 -> 10024 | X28: 선구+파워 | Z28: 스킬언더셔츠3 | AA28: =AA27+1 -> 20024 | AB28: 필드스킬
V29: 밤경기 | W29: =W28+1 -> 10025 | X29: 선구+컨택 | Z29: 글라스1 | AA29: =AA28+1 -> 20025 | AB29: 컨택
V30: 서브마린킬러 | W30: =W29+1 -> 10026 | X30: 컨택 | Z30: 글라스2 | AA30: =AA29+1 -> 20026 | AB30: 컨택
V31: 강심장1 | W31: =W30+1 -> 10027 | X31: 컨택 | Z31: 글라스3 | AA31: =AA30+1 -> 20027 | AB31: 컨택
V32: 강심장2 | W32: =W31+1 -> 10028 | X32: 컨택 | Z32: 스킬글라스1 | AA32: =AA31+1 -> 20028 | AB32: 컨택관련 스킬
... V50: 주자없음3 | W50: =W49+1 -> 10046 | X50: 선구 | Z50: 민첩성트레이너2 | AA50: =AA49+1 -> 20046 | AB50: 파워 +{0}, 주력 +{1}
V51: 분노맨G1 | W51: 10101 | X51: 아웃시 게이지
V52: 분노맨G2 | W52: =W51+1 -> 10102 | X52: 아웃시 게이지
V53: 분노맨G3 | W53: =W52+1 -> 10103 | X53: 아웃시 게이지
V54: 분위기맨G1 | W54: =W53+1 -> 10104 | X54: 안타시 게이지
V55: 분위기맨G2 | W55: =W54+1 -> 10105 | X55: 안타시 게이지
V56: 분위기맨G3 | W56: =W55+1 -> 10106 | X56: 안타시 게이지
V57: 불안감G1 | W57: =W56+1 -> 10107 | X57: 지고있는경우 게이지
V58: 불안감G2 | W58: =W57+1 -> 10108 | X58: 지고있는경우 게이지
V59: 불안감G3 | W59: =W58+1 -> 10109 | X59: 지고있는경우 게이지
V60: 안정감G1 | W60: =W59+1 -> 10110 | X60: 이기고 있는 경우 게이지
...
