Workbook

Sheet GearData
A1: idx | B1: name_id | C1: #name_id | D1: desc_id | E1: #desc_id | F1: gearType | G1: #장비 타입 | H1: att_refID | I1: #능력치 설명 | J1: 추가스킬1 | K1: 추가스킬2 | L1: att_lv
A2: 20001 | B2: ="GearName."&A2 -> GearName.20001 | C2: 글러브1 | D2: ="GearDesc."&A2 -> GearDesc.20001 | E2: 수비 +{0} | F2: Glove | G2: 손에 장착 | H2: 104 | I2: =IFERROR(VLOOKUP(H2, GearAttributes!$A$1:$J$3001, 10, FALSE),"") -> #수비증가 | J2: =IFERROR(VLOOKUP(H2, GearAttributes!$A$1:$K$3001, 11, FALSE),"") | K2: =IFERROR(VLOOKUP(H2, GearAttributes!$A$1:$L$3001, 12, FALSE),"") | L2: 1 | M2: =IFERROR(VLOOKUP(#REF!, '#level_value'!$A$1:$K$669, 11, FALSE),"")
A3: =A2+1 -> 20002 | B3: ="GearName."&A3 -> GearName.20002 | C3: 글러브2 | D3: ="GearDesc."&A3 -> GearDesc.20002 | E3: 수비 +{0} | F3: Glove | G3: 손에 장착 | H3: 104 | I3: =IFERROR(VLOOKUP(H3, GearAttributes!$A$1:$J$3001, 10, FALSE),"") -> #수비증가 | J3: =IFERROR(VLOOKUP(H3, GearAttributes!$A$1:$K$3001, 11, FALSE),"") | K3: =IFERROR(VLOOKUP(H3, GearAttributes!$A$1:$L$3001, 12, FALSE),"") | L3: 2 | M3: =IFERROR(VLOOKUP(#REF!, '#level_value'!$A$1:$K$669, 11, FALSE),"")
A4: =A3+1 -> 20003 | B4: ="GearName."&A4 -> GearName.20003 | C4: 글러브3 | D4: ="GearDesc."&A4 -> GearDesc.20003 | E4: 수비 +{0} | F4: Glove | G4: 손에 장착 | H4: 104 | I4: =IFERROR(VLOOKUP(H4, GearAttributes!$A$1:$J$3001, 10, FALSE),"") -> #수비증가 | J4: =IFERROR(VLOOKUP(H4, GearAttributes!$A$1:$K$3001, 11, FALSE),"") | K4: =IFERROR(VLOOKUP(H4, GearAttributes!$A$1:$L$3001, 12, FALSE),"") | L4: 3 | M4: =IFERROR(VLOOKUP(#REF!, '#level_value'!$A$1:$K$669, 11, FALSE),"")
A5: =A4+1 -> 20004 | B5: ="GearName."&A5 -> GearName.20004 | C5: 글러브4 | D5: ="GearDesc."&A5 -> GearDesc.20004 | E5: 수비 +{0} | F5: Glove | G5: 손에 장착 | H5: 104 | I5: =IFERROR(VLOOKUP(H5, GearAttributes!$A$1:$J$3001, 10, FALSE),"") -> #수비증가 | J5: =IFERROR(VLOOKUP(H5, GearAttributes!$A$1:$K$3001, 11, FALSE),"") | K5: =IFERROR(VLOOKUP(H5, GearAttributes!$A$1:$L$3001, 12, FALSE),"") | L5: 4 | M5: =IFERROR(VLOOKUP(#REF!, '#level_value'!$A$1:$K$669, 11, FALSE),"")
A6: =A5+1 -> 20005 | B6: ="GearName."&A6 -> GearName.20005 | C6: 글러브5 | D6: ="GearDesc."&A6 -> GearDesc.20005 | E6: 수비 +{0} | F6: Glove | G6: 손에 장착 | H6: 104 | I6: =IFERROR(VLOOKUP(H6, GearAttributes!$A$1:$J$3001, 10, FALSE),"") -> #수비증가 | J6: =IFERROR(VLOOKUP(H6, GearAttributes!$A$1:$K$3001, 11, FALSE),"") | K6: =IFERROR(VLOOKUP(H6, GearAttributes!$A$1:$L$3001, 12, FALSE),"") | L6: 5 | M6: =IFERROR(VLOOKUP(#REF!, '#level_value'!$A$1:$K$669, 11, FALSE),"")
A7: =A6+1 -> 20006 | B7: ="GearName."&A7 -> GearName.20006 | C7: 스킬글러브1 | D7: ="GearDesc."&A7 -> GearDesc.20006 | E7: 수비 +{0}, Lv{1} {2}스킬 장착 | F7: Glove | G7: 손에 장착 | H7: 134 | I7: =IFERROR(VLOOKUP(H7, GearAttributes!$A$1:$J$3001, 10, FALSE),"") -> #수비증가 | J7: =IFERROR(VLOOKUP(H7, GearAttributes!$A$1:$K$3001, 11, FALSE),"") -> 내야수비1 | K7: =IFERROR(VLOOKUP(H7, GearAttributes!$A$1:$L$3001, 12, FALSE),"") | L7: 1 | M7: =IFERROR(VLOOKUP(#REF!, '#level_value'!$A$1:$K$669, 11, FALSE),"")
A8: =A7+1 -> 20007 | B8: ="GearName."&A8 -> GearName.20007 | C8: 스킬글러브2 | D8: ="GearDesc."&A8 -> GearDesc.20007 | E8: 수비 +{0}, Lv{1} {2}스킬 장착 | F8: Glove | G8: 손에 장착 | H8: 134 | I8: =IFERROR(VLOOKUP(H8, GearAttributes!$A$1:$J$3001, 10, FALSE),"") -> #수비증가 | J8: =IFERROR(VLOOKUP(H8, GearAttributes!$A$1:$K$3001, 11, FALSE),"") -> 내야수비1 | K8: =IFERROR(VLOOKUP(H8, GearAttributes!$A$1:$L$3001, 12, FALSE),"") | L8: 2 | M8: =IFERROR(VLOOKUP(#REF!, '#level_value'!$A$1:$K$669, 11, FALSE),"")
A9: =A8+1 -> 20008 | B9: ="GearName."&A9 -> GearName.20008 | C9: 스킬글러브3 | D9: ="GearDesc."&A9 -> GearDesc.20008 | E9: 수비 +{0}, Lv{1} {2}스킬 장착 | F9: Glove | G9: 손에 장착 | H9: 134 | I9: =IFERROR(VLOOKUP(H9, GearAttributes!$A$1:$J$3001, 10, FALSE),"") -> #수비증가 | J9: =IFERROR(VLOOKUP(H9, GearAttributes!$A$1:$K$3001, 11, FALSE),"") -> 내야수비1 | K9: =IFERROR(VLOOKUP(H9, GearAttributes!$A$1:$L$3001, 12, FALSE),"") | L9: 3 | M9: =IFERROR(VLOOKUP(#REF!, '#level_value'!$A$1:$K$669, 11, FALSE),"")
A10: =A9+1 -> 20009 | B10: ="GearName."&A10 -> GearName.20009 | C10: 스킬글러브4 | D10: ="GearDesc."&A10 -> GearDesc.20009 | E10: 수비 +{0}, Lv{1} {2}스킬 장착 | F10: Glove | G10: 손에 장착 | H10: 134 | I10: =IFERROR(VLOOKUP(H10, GearAttributes!$A$1:$J$3001, 10, FALSE),"") -> #수비증가 | J10: =IFERROR(VLOOKUP(H10, GearAttributes!$A$1:$K$3001, 11, FALSE),"") -> 내야수비1 | K10: =IFERROR(VLOOKUP(H10, GearAttributes!$A$1:$L$3001, 12, FALSE),"") | L10: 4 | M10: =IFERROR(VLOOKUP(#REF!, '#level_value'!$A$1:$K$669, 11, FALSE),"")
A11: =A10+1 -> 20010 | B11: ="GearName."&A11 -> GearName.20010 | C11: 스킬글러브5 | D11: ="GearDesc."&A11 -> GearDesc.20010 | E11: 수비 +{0}, Lv{1} {2}스킬 장착 | F11: Glove | G11: 손에 장착 | H11: 134 | I11: =IFERROR(VLOOKUP(H11, GearAttributes!$A$1:$J$3001, 10, FALSE),"") -> #수비증가 | J11: =IFERROR(VLOOKUP(H11, GearAttributes!$A$1:$K$3001, 11, FALSE),"") -> 내야수비1 | K11: =IFERROR(VLOOKUP(H11, GearAttributes!$A$1:$L$3001, 12, FALSE),"") | L11: 5 | M11: =IFERROR(VLOOKUP(#REF!, '#level_value'!$A$1:$K$669, 11, FALSE),"")
A12: =A11+1 -> 20011 | B12: ="GearName."&A12 -> GearName.20011 | C12: 스파이크1 | D12: ="GearDesc."&A12 -> GearDesc.20011 | E12: 주루 +{0} | F12: Spike | G12: 발에 장착 | H12: 106 | I12: =IFERROR(VLOOKUP(H12, GearAttributes!$A$1:$J$3001, 10, FALSE),"") -> #주루증가 | J12: =IFERROR(VLOOKUP(H12, GearAttributes!$A$1:$K$3001, 11, FALSE),"") | K12: =IFERROR(VLOOKUP(H12, GearAttributes!$A$1:$L$3001, 12, FALSE),"") | L12: 1 | M12: =IFERROR(VLOOKUP(#REF!, '#level_value'!$A$1:$K$669, 11, FALSE),"")
A13: =A12+1 -> 20012 | B13: ="GearName."&A13 -> GearName.20012 | C13: 스파이크2 | D13: ="GearDesc."&A13 -> GearDesc.20012 | E13: 주루 +{0} | F13: Spike | G13: 발에 장착 | H13: 106 | I13: =IFERROR(VLOOKUP(H13, GearAttributes!$A$1:$J$3001, 10, FALSE),"") -> #주루증가 | J13: =IFERROR(VLOOKUP(H13, GearAttributes!$A$1:$K$3001, 11, FALSE),"") | K13: =IFERROR(VLOOKUP(H13, GearAttributes!$A$1:$L$3001, 12, FALSE),"") | L13: 2 | M13: =IFERROR(VLOOKUP(#REF!, '#level_value'!$A$1:$K$669, 11, FALSE),"")
A14: =A13+1 -> 20013 | B14: ="GearName."&A14 -> GearName.20013 | C14: 스파이크3 | D14: ="GearDesc."&A14 -> GearDesc.20013 | E14: 주루 +{0} | F14: Spike | G14: 발에 장착 | H14: 106 | I14: =IFERROR(VLOOKUP(H14, GearAttributes!$A$1:$J$3001, 10, FALSE),"") -> #주루증가 | J14: =IFERROR(VLOOKUP(H14, GearAttributes!$A$1:$K$3001, 11, FALSE),"") | K14: =IFERROR(VLOOKUP(H14, GearAttributes!$A$1:$L$3001, 12, FALSE),"") | L14: 3 | M14: =IFERROR(VLOOKUP(#REF!, '#level_value'!$A$1:$K$669, 11, FALSE),"")
... A81: =A80+1 -> 20080 | B81: ="GearName."&A81 -> GearName.20080 | C81: 민첩성트레이너5 | D81: ="GearDesc."&A81 -> GearDesc.20080 | E81: 주루 +{0}, Lv{1} {2}스킬 장착 | F81: Accessory | G81: 악세사리 | H81: 136 | I81: =IFERROR(VLOOKUP(H81, GearAttributes!$A$1:$J$3001, 10, FALSE),"") -> #주루증가 | J81: =IFERROR(VLOOKUP(H81, GearAttributes!$A$1:$K$3001, 11, FALSE),"") -> 주력1 | K81: =IFERROR(VLOOKUP(H81, GearAttributes!$A$1:$L$3001, 12, FALSE),"") | L81: 3 | M81: =IFERROR(VLOOKUP(#REF!, '#level_value'!$A$1:$K$669, 11, FALSE),"")

Sheet GearAttributes
A1: ref_idx | B1: pow | C1: con | D1: vis | E1: fld | F1: thw | G1: spd | H1: skill1 | I1: skill2 | J1: 설명 | K1: 추가스킬 1 | L1: 추가스킬2
A2: 101 | B2: 1 | J2: #파워증가
A3: =A2+1 -> 102 | C3: 1 | J3: #컨택증가
A4: =A3+1 -> 103 | D4: 1 | J4: #선구증가
A5: =A4+1 -> 104 | E5: 1 | J5: #수비증가
A6: =A5+1 -> 105 | F6: 1 | J6: #송구증가
A7: =A6+1 -> 106 | G7: 1 | J7: #주루증가
A8: =A7+1 -> 107 | B8: 1 | C8: 1 | J8: #파워+컨택
A9: =A8+1 -> 108 | B9: 1 | D9: 1 | J9: #파워+선구
A10: =A9+1 -> 109 | B10: 1 | E10: 1 | J10: #파워+수비
A11: =A10+1 -> 110 | B11: 1 | F11: 1 | J11: #파워+송구
A12: =A11+1 -> 111 | B12: 1 | G12: 1 | J12: #파워+주루
A13: =A12+1 -> 112 | C13: 1 | D13: 1 | J13: #컨택+선구
A14: =A13+1 -> 113 | C14: 1 | E14: 1 | J14: #컨택+수비
A15: =A14+1 -> 114 | C15: 1 | F15: 1 | J15: #컨택+송구
A16: =A15+1 -> 115 | C16: 1 | G16: 1 | J16: #컨택+주루
A17: =A16+1 -> 116 | D17: 1 | E17: 1 | J17: #선구+수비
A18: =A17+1 -> 117 | D18: 1 | F18: 1 | J18: #선구+송구
A19: =A18+1 -> 118 | D19: 1 | G19: 1 | J19: #선구+수비
A20: =A19+1 -> 119 | E20: 1 | F20: 1 | J20: #수비+송구
A21: =A20+1 -> 120 | E21: 1 | G21: 1 | J21: #수비+주루
A22: =A21+1 -> 121 | F22: 1 | G22: 1 | J22: #송구+주루
A23: =A22+1 -> 122 | B23: 1 | C23: 1 | D23: 1 | J23: #파워+컨택+선구
A24: =A23+1 -> 123 | B24: 1 | D24: 1 | E24: 1 | J24: #파워+선구+수비
A25: =A24+1 -> 124 | B25: 1 | E25: 1 | F25: 1 | J25: #파워+수비+송구
A26: =A25+1 -> 125 | B26: 1 | F26: 1 | G26: 1 | J26: #파워+송구+주루
A27: =A26+1 -> 126 | C27: 1 | D27: 1 | E27: 1 | J27: #컨택+선구+수비
A28: =A27+1 -> 127 | C28: 1 | E28: 1 | F28: 1 | J28: #컨택+수비+송구
A29: =A28+1 -> 128 | C29: 1 | F29: 1 | G29: 1 | J29: #컨택+송구+주루
A30: =A29+1 -> 129 | D30: 1 | E30: 1 | F30: 1 | J30: #선구+수비+송구
A31: =A30+1 -> 130 | D31: 1 | F31: 1 | G31: 1 | J31: #선구+송구+주루
A32: =A31+1 -> 131 | B32: 1 | H32: 10012 | J32: #파워증가 | K32: =IFERROR(VLOOKUP(H32, '#조건테이블'!$Q$8:$S$300, 2, FALSE),"") -> 초구1
A33: =A32+1 -> 132 | C33: 1 | H33: 10007 | J33: #컨택증가 | K33: =IFERROR(VLOOKUP(H33, '#조건테이블'!$Q$8:$S$300, 2, FALSE),"") -> 좌완킬러1
A34: =A33+1 -> 133 | D34: 1 | H34: 10001 | J34: #선구증가 | K34: =IFERROR(VLOOKUP(H34, '#조건테이블'!$Q$8:$S$300, 2, FALSE),"") -> 집중력1
A35: =A34+1 -> 134 | E35: 1 | H35: 10203 | J35: #수비증가 | K35: =IFERROR(VLOOKUP(H35, '#조건테이블'!$Q$8:$S$300, 2, FALSE),"") -> 내야수비1
A36: =A35+1 -> 135 | F36: 1 | H36: 10221 | J36: #송구증가 | K36: =IFERROR(VLOOKUP(H36, '#조건테이블'!$Q$8:$S$300, 2, FALSE),"") -> 내야송구1
A37: =A36+1 -> 136 | G37: 1 | H37: 10308 | J37: #주루증가 | K37: =IFERROR(VLOOKUP(H37, '#조건테이블'!$Q$8:$S$300, 2, FALSE),"") -> 주력1

Sheet #level_value
A1: ="# 장비 idx " &A3& VLOOKUP(A3,GearData!A$2:C$491,5,FALSE) -> #REF!
A2: idx | B2: lv | C2: Key | D2: #Key | E2: Con | F2: #Condition | G2: Per | H2: Val
A3: 20001 | B3: 1 | C3: =VLOOKUP(D3, '#조건테이블'!$E$8:$F$98, 2, FALSE) -> 4 | D3: Fielding | E3: =VLOOKUP(F3, '#조건테이블'!$A$8:$B$98, 2, FALSE) -> 1 | F3: NoCondition | G3: 0 | H3: 3 | J3: =""""&B3&""":{"""&C$2&""":"&C3&","""&E$2&""":"&E3&","""&H$2&""":"&H3&"}" -> "1":{"Key":4,"Con":1,"Val":3} | K3: ="{"&J3&","&J4&","&J5&"}" -> {"1":{"Key":4,"Con":1,"Val":3},"2":{"Key":4,"Con":1,"Val":6},"3":{"Key":4,"Con":1,"Val":9}}
B4: 2 | C4: =VLOOKUP(D4, '#조건테이블'!$E$8:$F$98, 2, FALSE) -> 4 | D4: Fielding | E4: =VLOOKUP(F4, '#조건테이블'!$A$8:$B$98, 2, FALSE) -> 1 | F4: NoCondition | G4: 0 | H4: 6 | J4: =""""&B4&""":{"""&C$2&""":"&C4&","""&E$2&""":"&E4&","""&H$2&""":"&H4&"}" -> "2":{"Key":4,"Con":1,"Val":6}
B5: 3 | C5: =VLOOKUP(D5, '#조건테이블'!$E$8:$F$98, 2, FALSE) -> 4 | D5: Fielding | E5: =VLOOKUP(F5, '#조건테이블'!$A$8:$B$98, 2, FALSE) -> 1 | F5: NoCondition | G5: 0 | H5: 9 | J5: =""""&B5&""":{"""&C$2&""":"&C5&","""&E$2&""":"&E5&","""&H$2&""":"&H5&"}" -> "3":{"Key":4,"Con":1,"Val":9}
A7: ="# 장비 idx " &A9& VLOOKUP(A9,GearData!A$2:C$491,5,FALSE) -> #REF!
A8: idx | B8: lv | C8: Key | D8: #Key | E8: Con | F8: #Condition | G8: Per | H8: Val
A9: 20002 | B9: 1 | C9: =VLOOKUP(D9, '#조건테이블'!$E$8:$F$98, 2, FALSE) -> 4 | D9: Fielding | E9: =VLOOKUP(F9, '#조건테이블'!$A$8:$B$98, 2, FALSE) -> 1 | F9: NoCondition | G9: 0 | H9: 5 | J9: =""""&B9&""":{"""&C$2&""":"&C9&","""&E$2&""":"&E9&","""&H$2&""":"&H9&"}" -> "1":{"Key":4,"Con":1,"Val":5} | K9: ="{"&J9&","&J10&","&J11&"}" -> {"1":{"Key":4,"Con":1,"Val":5},"2":{"Key":4,"Con":1,"Val":10},"3":{"Key":4,"Con":1,"Val":15}}
B10: 2 | C10: =VLOOKUP(D10, '#조건테이블'!$E$8:$F$98, 2, FALSE) -> 4 | D10: Fielding | E10: =VLOOKUP(F10, '#조건테이블'!$A$8:$B$98, 2, FALSE) -> 1 | F10: NoCondition | G10: 0 | H10: 10 | J10: =""""&B10&""":{"""&C$2&""":"&C10&","""&E$2&""":"&E10&","""&H$2&""":"&H10&"}" -> "2":{"Key":4,"Con":1,"Val":10}
B11: 3 | C11: =VLOOKUP(D11, '#조건테이블'!$E$8:$F$98, 2, FALSE) -> 4 | D11: Fielding | E11: =VLOOKUP(F11, '#조건테이블'!$A$8:$B$98, 2, FALSE) -> 1 | F11: NoCondition | G11: 0 | H11: 15 | J11: =""""&B11&""":{"""&C$2&""":"&C11&","""&E$2&""":"&E11&","""&H$2&""":"&H11&"}" -> "3":{"Key":4,"Con":1,"Val":15}
A13: ="# 장비 idx " &A15& VLOOKUP(A15,GearData!A$2:C$491,5,FALSE) -> #REF!
A14: idx | B14: lv | C14: Key | D14: #Key | E14: Con | F14: #Condition | G14: Per | H14: Val
A15: 20003 | B15: 1 | C15: =VLOOKUP(D15, '#조건테이블'!$E$8:$F$98, 2, FALSE) -> 4 | D15: Fielding | E15: =VLOOKUP(F15, '#조건테이블'!$A$8:$B$98, 2, FALSE) -> 1 | F15: NoCondition | G15: 0 | H15: 10 | J15: =""""&B15&""":{"""&C$2&""":"&C15&","""&E$2&""":"&E15&","""&H$2&""":"&H15&"}" -> "1":{"Key":4,"Con":1,"Val":10} | K15: ="{"&J15&","&J16&","&J17&"}" -> {"1":{"Key":4,"Con":1,"Val":10},"2":{"Key":4,"Con":1,"Val":20},"3":{"Key":4,"Con":1,"Val":30}}
B16: 2 | C16: =VLOOKUP(D16, '#조건테이블'!$E$8:$F$98, 2, FALSE) -> 4 | D16: Fielding | E16: =VLOOKUP(F16, '#조건테이블'!$A$8:$B$98, 2, FALSE) -> 1 | F16: NoCondition | G16: 0 | H16: 20 | J16: =""""&B16&""":{"""&C$2&""":"&C16&","""&E$2&""":"&E16&","""&H$2&""":"&H16&"}" -> "2":{"Key":4,"Con":1,"Val":20}
B17: 3 | C17: =VLOOKUP(D17, '#조건테이블'!$E$8:$F$98, 2, FALSE) -> 4 | D17: Fielding | E17: =VLOOKUP(F17, '#조건테이블'!$A$8:$B$98, 2, FALSE) -> 1 | F17: NoCondition | G17: 0 | H17: 30 | J17: =""""&B17&""":{"""&C$2&""":"&C17&","""&E$2&""":"&E17&","""&H$2&""":"&H17&"}" -> "3":{"Key":4,"Con":1,"Val":30}
A19: ="# 장비 idx " &A21& VLOOKUP(A21,GearData!A$2:C$491,5,FALSE) -> #REF!
A20: idx | B20: lv | C20: Key | D20: #Key | E20: Con | F20: #Condition | G20: Per | H20: Val
A21: 20004 | B21: 1 | C21: =VLOOKUP(D21, '#조건테이블'!$E$8:$F$98, 2, FALSE) -> 14 | D21: InfieldDiving | E21: =VLOOKUP(F21, '#조건테이블'!$A$8:$B$98, 2, FALSE) -> 1 | F21: NoCondition | G21: 0 | H21: 45 | I21: val이 확률 | J21: =""""&B21&""":{"""&C$2&""":"&C21&","""&E$2&""":"&E21&","""&H$2&""":"&H21&"}" -> "1":{"Key":14,"Con":1,"Val":45} | K21: ="{"&J21&"}" -> {"1":{"Key":14,"Con":1,"Val":45}}
A23: ="# 장비 idx " &A25& VLOOKUP(A25,GearData!A$2:C$491,5,FALSE) -> #REF!
A24: idx | B24: lv | C24: Key | D24: #Key | E24: Con | F24: #Condition | G24: Per | H24: Val
A25: 20005 | B25: 1 | C25: =VLOOKUP(D25, '#조건테이블'!$E$8:$F$98, 2, FALSE) -> 15 | D25: OutfieldDiving | E25: =VLOOKUP(F25, '#조건테이블'!$A$8:$B$98, 2, FALSE) -> 1 | F25: NoCondition | G25: 0 | H25: 45 | I25: val이 확률 | J25: =""""&B25&""":{"""&C$2&""":"&C25&","""&E$2&""":"&E25&","""&H$2&""":"&H25&"}" -> "1":{"Key":15,"Con":1,"Val":45} | K25: ="{"&J25&"}" -> {"1":{"Key":15,"Con":1,"Val":45}}
A27: ="# 장비 idx " &A29& VLOOKUP(A29,GearData!A$2:C$491,5,FALSE) -> #REF!
A28: idx | B28: lv | C28: Key | D28: #Key | E28: Con | F28: #Condition | G28: Per | H28: Val
A29: 20006 | B29: 1 | C29: =VLOOKUP(D29, '#조건테이블'!$E$8:$F$98, 2, FALSE) -> 13 | D29: SkillGear | E29: 10211 | F29: 포수 블록킹lv3 | G29: 0 | H29: 3 | I29: 스킬레벨 | J29: =""""&B29&""":{"""&C$2&""":"&C29&","""&E$2&""":"&E29&","""&H$2&""":"&H29&"}" -> "1":{"Key":13,"Con":10211,"Val":3} | K29: ="{"&J29&"}" -> {"1":{"Key":13,"Con":10211,"Val":3}}
E30: #스킬 idx
A31: ="# 장비 idx " &A33& VLOOKUP(A33,GearData!A$2:C$491,5,FALSE) -> #REF!
A32: idx | B32: lv | C32: Key | D32: #Key | E32: Con | F32: #Condition | G32: Per | H32: Val
A33: 20007 | B33: 1 | C33: =VLOOKUP(D33, '#조건테이블'!$E$8:$F$98, 2, FALSE) -> 6 | D33: Speed | E33: =VLOOKUP(F33, '#조건테이블'!$A$8:$B$98, 2, FALSE) -> 1 | F33: NoCondition | G33: 0 | H33: 3 | J33: =""""&B33&""":{"""&C$2&""":"&C33&","""&E$2&""":"&E33&","""&H$2&""":"&H33&"}" -> "1":{"Key":6,"Con":1,"Val":3} | K33: ="{"&J33&","&J34&","&J35&"}" -> {"1":{"Key":6,"Con":1,"Val":3},"2":{"Key":6,"Con":1,"Val":6},"3":{"Key":6,"Con":1,"Val":9}}
B34: 2 | C34: =VLOOKUP(D34, '#조건테이블'!$E$8:$F$98, 2, FALSE) -> 6 | D34: Speed | E34: =VLOOKUP(F34, '#조건테이블'!$A$8:$B$98, 2, FALSE) -> 1 | F34: NoCondition | G34: 0 | H34: 6 | J34: =""""&B34&""":{"""&C$2&""":"&C34&","""&E$2&""":"&E34&","""&H$2&""":"&H34&"}" -> "2":{"Key":6,"Con":1,"Val":6}
B35: 3 | C35: =VLOOKUP(D35, '#조건테이블'!$E$8:$F$98, 2, FALSE) -> 6 | D35: Speed | E35: =VLOOKUP(F35, '#조건테이블'!$A$8:$B$98, 2, FALSE) -> 1 | F35: NoCondition | G35: 0 | H35: 9 | J35: =""""&B35&""":{"""&C$2&""":"&C35&","""&E$2&""":"&E35&","""&H$2&""":"&H35&"}" -> "3":{"Key":6,"Con":1,"Val":9}
A37: ="# 장비 idx " &A39& VLOOKUP(A39,GearData!A$2:C$491,5,FALSE) -> #REF!
A38: idx | B38: lv | C38: Key | D38: #Key | E38: Con | F38: #Condition | G38: Per | H38: Val
A39: 20008 | B39: 1 | C39: =VLOOKUP(D39, '#조건테이블'!$E$8:$F$98, 2, FALSE) -> 6 | D39: Speed | E39: =VLOOKUP(F39, '#조건테이블'!$A$8:$B$98, 2, FALSE) -> 1 | F39: NoCondition | G39: 0 | H39: 5 | J39: =""""&B39&""":{"""&C$2&""":"&C39&","""&E$2&""":"&E39&","""&H$2&""":"&H39&"}" -> "1":{"Key":6,"Con":1,"Val":5} | K39: ="{"&J39&","&J40&","&J41&"}" -> {"1":{"Key":6,"Con":1,"Val":5},"2":{"Key":6,"Con":1,"Val":10},"3":{"Key":6,"Con":1,"Val":15}}
B40: 2 | C40: =VLOOKUP(D40, '#조건테이블'!$E$8:$F$98, 2, FALSE) -> 6 | D40: Speed | E40: =VLOOKUP(F40, '#조건테이블'!$A$8:$B$98, 2, FALSE) -> 1 | F40: NoCondition | G40: 0 | H40: 10 | J40: =""""&B40&""":{"""&C$2&""":"&C40&","""&E$2&""":"&E40&","""&H$2&""":"&H40&"}" -> "2":{"Key":6,"Con":1,"Val":10}
B41: 3 | C41: =VLOOKUP(D41, '#조건테이블'!$E$8:$F$98, 2, FALSE) -> 6 | D41: Speed | E41: =VLOOKUP(F41, '#조건테이블'!$A$8:$B$98, 2, FALSE) -> 1 | F41: NoCondition | G41: 0 | H41: 15 | J41: =""""&B41&""":{"""&C$2&""":"&C41&","""&E$2&""":"&E41&","""&H$2&""":"&H41&"}" -> "3":{"Key":6,"Con":1,"Val":15}
A43: ="# 장비 idx " &A45& VLOOKUP(A45,GearData!A$2:C$491,5,FALSE) -> #REF!
A44: idx | B44: lv | C44: Key | D44: #Key | E44: Con | F44: #Condition | G44: Per | H44: Val
A45: 20009 | B45: 1 | C45: =VLOOKUP(D45, '#조건테이블'!$E$8:$F$98, 2, FALSE) -> 6 | D45: Speed | E45: =VLOOKUP(F45, '#조건테이블'!$A$8:$B$98, 2, FALSE) -> 1 | F45: NoCondition | G45: 0 | H45: 10 | J45: =""""&B45&""":{"""&C$2&""":"&C45&","""&E$2&""":"&E45&","""&H$2&""":"&H45&"}" -> "1":{"Key":6,"Con":1,"Val":10} | K45: ="{"&J45&","&J46&","&J47&"}" -> {"1":{"Key":6,"Con":1,"Val":10},"2":{"Key":6,"Con":1,"Val":20},"3":{"Key":6,"Con":1,"Val":30}}
B46: 2 | C46: =VLOOKUP(D46, '#조건테이블'!$E$8:$F$98, 2, FALSE) -> 6 | D46: Speed | E46: =VLOOKUP(F46, '#조건테이블'!$A$8:$B$98, 2, FALSE) -> 1 | F46: NoCondition | G46: 0 | H46: 20 | J46: =""""&B46&""":{"""&C$2&""":"&C46&","""&E$2&""":"&E46&","""&H$2&""":"&H46&"}" -> "2":{"Key":6,"Con":1,"Val":20}
B47: 3 | C47: =VLOOKUP(D47, '#조건테이블'!$E$8:$F$98, 2, FALSE) -> 6 | D47: Speed | E47: =VLOOKUP(F47, '#조건테이블'!$A$8:$B$98, 2, FALSE) -> 1 | F47: NoCondition | G47: 0 | H47: 30 | J47: =""""&B47&""":{"""&C$2&""":"&C47&","""&E$2&""":"&E47&","""&H$2&""":"&H47&"}" -> "3":{"Key":6,"Con":1,"Val":30}
...

Sheet #조건테이블
A7: #KOBSkillCondition 스킬조건 | E7: #KOBGearKey 장비키 | I7: #KOBGearType | M7: #KOBRarity | Q7: #SKILL | S7: 관여 능력
A8: NoCondition | B8: 1 | E8: Power | F8: 1 | I8: Hitting | J8: 1 | M8: COMMON | N8: 1 | Q8: 10001 | R8: 집중력1 | S8: 선구
A9: Cumulative | B9: 2 | E9: Contact | F9: 2 | I9: Pysical | J9: 2 | M9: RARE | N9: 2 | Q9: =Q8+1 -> 10002 | R9: 집중력2 | S9: 선구
A10: RightPitcher | B10: 3 | E10: Vision | F10: 3 | I10: Special | J10: 3 | M10: EPIC | N10: 3 | Q10: =Q9+1 -> 10003 | R10: 집중력3 | S10: 선구
A11: LeftPitcher | B11: 4 | E11: Fielding | F11: 4 | I11: Wide | J11: 4 | M11: LEGENDARY | N11: 4 | Q11: =Q10+1 -> 10004 | R11: 우완킬러1 | S11: 컨택
A12: AfterHit | B12: 5 | E12: Throwing | F12: 5 | M12: BLACK | N12: 5 | Q12: =Q11+1 -> 10005 | R12: 우완킬러2 | S12: 컨택
A13: MainActivated | B13: 6 | E13: Speed | F13: 6 | Q13: =Q12+1 -> 10006 | R13: 우완킬러3 | S13: 컨택
A14: Walkoff | B14: 7 | E14: RunningSkill | F14: 7 | Q14: =Q13+1 -> 10007 | R14: 좌완킬러1 | S14: 파워
A15: FirstPitch | B15: 8 | E15: HittingSpeed | F15: 8 | Q15: =Q14+1 -> 10008 | R15: 좌완킬러2 | S15: 파워
A16: BreakballHit | B16: 9 | E16: CheckSwing | F16: 9 | G16: #체크스윙 별도 | Q16: =Q15+1 -> 10009 | R16: 좌완킬러3 | S16: 파워
A17: FastballHit | B17: 10 | E17: AllHitting | F17: 10 | Q17: =Q16+1 -> 10010 | R17: 끝내기안타 | S17: 컨택
A18: LinedriveHit | B18: 11 | E18: AllDefense | F18: 11 | Q18: =Q17+1 -> 10011 | R18: 끝내기홈런 | S18: 파워
A19: FlyHit | B19: 12 | E19: FieldSkill | F19: 12 | Q19: =Q18+1 -> 10012 | R19: 초구1 | S19: 파워
A20: RunAndHit | B20: 13 | E20: SkillGear | F20: 13 | G20: 장비장착시 스킬 | Q20: =Q19+1 -> 10013 | R20: 초구2 | S20: 파워
A21: HomeMatch | B21: 14 | E21: InfieldDiving | F21: 14 | G21: #내야 다이빙 별도 | Q21: =Q20+1 -> 10014 | R21: 초구3 | S21: 파워
A22: AwayMatch | B22: 15 | E22: OutFieldDiving | F22: 15 | G22: #외야 다이빙 별도 | Q22: =Q21+1 -> 10015 | R22: 변화구1 | S22: 타구속도
A23: DayMatch | B23: 16 | E23: TimingPlus | F23: 16 | G23: #타이밍 플러스 별도 | Q23: =Q22+1 -> 10016 | R23: 변화구2 | S23: 타구속도
A24: NightMatch | B24: 17 | Q24: =Q23+1 -> 10017 | R24: 직구1 | S24: 타구속도
A25: UnderPitcher | B25: 18 | Q25: =Q24+1 -> 10018 | R25: 직구2 | S25: 타구속도
A26: TwoOut | B26: 19 | Q26: =Q25+1 -> 10019 | R26: 라인드라이브 | S26: 타구속도
A27: TwoStrike | B27: 20 | Q27: =Q26+1 -> 10020 | R27: 플라이볼 | S27: 타구속도
A28: Chance | B28: 21 | Q28: =Q27+1 -> 10021 | R28: 히트앤드런 | S28: 타구속도
A29: Losing1 | B29: 22 | Q29: =Q28+1 -> 10022 | R29: 홈경기 | S29: 컨택
A30: Losing2 | B30: 23 | Q30: =Q29+1 -> 10023 | R30: 원정경기 | S30: 파워
A31: InningFirst | B31: 24 | Q31: =Q30+1 -> 10024 | R31: 낮경기 | S31: 선구+파워
A32: FullBase | B32: 25 | Q32: =Q31+1 -> 10025 | R32: 밤경기 | S32: 선구+컨택
A33: Winning1 | B33: 26 | Q33: =Q32+1 -> 10026 | R33: 서브마린킬러 | S33: 컨택
A34: Winning2 | B34: 27 | Q34: =Q33+1 -> 10027 | R34: 강심장1 | S34: 컨택
A35: NoRunner | B35: 28 | Q35: =Q34+1 -> 10028 | R35: 강심장2 | S35: 컨택
... A53: Inning789 | B53: 46 | Q53: =Q52+1 -> 10046 | R53: 주자없음3 | S53: 선구
Q54: 10101 | R54: 분노맨G1 | S54: 아웃시 게이지
Q55: =Q54+1 -> 10102 | R55: 분노맨G2 | S55: 아웃시 게이지
Q56: =Q55+1 -> 10103 | R56: 분노맨G3 | S56: 아웃시 게이지
Q57: =Q56+1 -> 10104 | R57: 분위기맨G1 | S57: 안타시 게이지
Q58: =Q57+1 -> 10105 | R58: 분위기맨G2 | S58: 안타시 게이지
Q59: =Q58+1 -> 10106 | R59: 분위기맨G3 | S59: 안타시 게이지
Q60: =Q59+1 -> 10107 | R60: 불안감G1 | S60: 지고있는경우 게이지
Q61: =Q60+1 -> 10108 | R61: 불안감G2 | S61: 지고있는경우 게이지
Q62: =Q61+1 -> 10109 | R62: 불안감G3 | S62: 지고있는경우 게이지
Q63: =Q62+1 -> 10110 | R63: 안정감G1 | S63: 이기고 있는 경우 게이지
...

Sheet 장비구상용
A1: 일부 장비는 스킬을 장착해줌 Lv1~Lv3까지
A2: 장비 타입은 글러브/스파이크/헬멧/셔츠/글라스/배팅글로브/게이지/트레이너의 7종이다
A3: 같은장비 두개를 장착할 수 없도록 세팅시 종류별 1개만 장착가능하게 세팅해준다
A6: idx | B6: 이름 | C6: 특징 | D6: Lv1 | E6: Lv2 | F6: Lv3 | G6: Lv3 | H6: Lv3
A7: 20001 | B7: 글러브1 | C7: 수비 | D7: 3 | E7: 6 | F7: 9
A8: =A7+1 -> 20002 | B8: 글러브2 | C8: 수비 | D8: 5 | E8: 10 | F8: 15
A9: =A8+1 -> 20003 | B9: 글러브3 | C9: 수비 | D9: 10 | E9: 20 | F9: 30
A10: =A9+1 -> 20004 | B10: 내야스킬글러브1 | C10: 다이빙캐치 Lv3 | D10: 1레벨이 Max
A11: =A10+1 -> 20005 | B11: 외야스킬글러브2 | C11: 다이빙캐치 Lv3 | D11: 1레벨이 Max
A12: =A11+1 -> 20006 | B12: 포수스킬글러브3 | C12: 포수블록킹 Lv3 | D12: 1레벨이 Max
A13: =A12+1 -> 20007 | B13: 스파이크1 | C13: 주력
A14: =A13+1 -> 20008 | B14: 스파이크2 | C14: 주력
A15: =A14+1 -> 20009 | B15: 스파이크3 | C15: 주력
A16: =A15+1 -> 20010 | B16: 스킬스파이크1 | C16: 병살저지 Lv3 | D16: 1레벨이 Max
A17: =A16+1 -> 20011 | B17: 스킬스파이크2 | C17: 내야안타 Lv3 | D17: 1레벨이 Max
A18: =A17+1 -> 20012 | B18: 스킬스파이크3 | C18: 홈돌진 Lv3 | D18: 1레벨이 Max
A19: =A18+1 -> 20013 | B19: 헬멧1 | C19: 선구 | D19: 2 | E19: 4 | F19: 7
A20: =A19+1 -> 20014 | B20: 헬멧2 | C20: 선구 | D20: 3 | E20: 6 | F20: 10
A21: =A20+1 -> 20015 | B21: 헬멧3 | C21: 선구 | D21: 5 | E21: 10 | F21: 15
A22: =A21+1 -> 20016 | B22: 스킬 헬멧1 | C22: 체크스윙 Lv3 | D22: 1레벨이 Max
A23: =A22+1 -> 20017 | B23: 스킬 헬멧2 | C23: 타이밍 plus | D23: 1레벨이 Max
A24: =A23+1 -> 20018 | B24: 스킬 헬멧3 | C24: 미구상
A25: =A24+1 -> 20019 | B25: 언더셔츠1 | C25: 송구 | D25: 3 | E25: 6 | F25: 9
A26: =A25+1 -> 20020 | B26: 언더셔츠2 | C26: 송구 | D26: 5 | E26: 10 | F26: 15
A27: =A26+1 -> 20021 | B27: 언더셔츠3 | C27: 송구 | D27: 10 | E27: 20 | F27: 30
A28: =A27+1 -> 20022 | B28: 스킬언더셔츠1 | C28: 내야송구 Lv3 | D28: 1레벨이 Max
A29: =A28+1 -> 20023 | B29: 스킬언더셔츠1 | C29: 외야 어시스트 Lv3 | D29: 1레벨이 Max
A30: =A29+1 -> 20024 | B30: 스킬언더셔츠1 | C30: 포수 도루2 Lv3 | D30: 1레벨이 Max
A31: =A30+1 -> 20025 | B31: 글라스1 | C31: 컨택 | D31: 2 | E31: 4 | F31: 7
A32: =A31+1 -> 20026 | B32: 글라스2 | C32: 컨택 | D32: 3 | E32: 6 | F32: 10
A33: =A32+1 -> 20027 | B33: 글라스3 | C33: 컨택 | D33: 5 | E33: 10 | F33: 15
A34: =A33+1 -> 20028 | B34: 스킬 글라스1 | C34: 낮경기 Lv3 | D34: 1레벨이 Max
A35: =A34+1 -> 20029 | B35: 스킬 글라스2 | C35: 밤경기 Lv3 | D35: 1레벨이 Max
A36: =A35+1 -> 20030 | B36: 스킬 글라스3 | C36: 미구상
A37: =A36+1 -> 20031 | B37: 배팅글러브1 | C37: 파워 | D37: 2 | E37: 4 | F37: 7
A38: =A37+1 -> 20032 | B38: 배팅글러브2 | C38: 파워 | D38: 3 | E38: 6 | F38: 10
A39: =A38+1 -> 20033 | B39: 배팅글러브3 | C39: 파워 | D39: 5 | E39: 10 | F39: 15
A40: =A39+1 -> 20034 | B40: 스킬 배팅글러브1 | C40: 라인드라이브 Lv3 | D40: 1레벨이 Max
A41: =A40+1 -> 20035 | B41: 스킬 배팅글러브2 | C41: 플라이볼 Lv3 | D41: 1레벨이 Max
A42: =A41+1 -> 20036 | B42: 스킬 배팅글러브3 | C42: 미구상
...
